INFO:     Will watch for changes in these directories: ['/home/saketh/Projects/dsa']
INFO:     Uvicorn running on http://0.0.0.0:8000 (Press CTRL+C to quit)
INFO:     Started reloader process [19416] using WatchFiles
/home/saketh/.local/lib/python3.10/site-packages/pydantic/_internal/_fields.py:198: UserWarning: Field name "app_name" in "Settings" shadows an attribute in parent "ISettings"
  warnings.warn(
/home/saketh/.local/lib/python3.10/site-packages/pydantic/_internal/_fields.py:198: UserWarning: Field name "version" in "Settings" shadows an attribute in parent "ISettings"
  warnings.warn(
/home/saketh/.local/lib/python3.10/site-packages/pydantic/_internal/_fields.py:198: UserWarning: Field name "debug" in "Settings" shadows an attribute in parent "ISettings"
  warnings.warn(
/home/saketh/.local/lib/python3.10/site-packages/pydantic/_internal/_fields.py:198: UserWarning: Field name "database_url" in "Settings" shadows an attribute in parent "ISettings"
  warnings.warn(
/home/saketh/.local/lib/python3.10/site-packages/pydantic/_internal/_fields.py:198: UserWarning: Field name "db_pool_min_size" in "Settings" shadows an attribute in parent "ISettings"
  warnings.warn(
/home/saketh/.local/lib/python3.10/site-packages/pydantic/_internal/_fields.py:198: UserWarning: Field name "db_pool_max_size" in "Settings" shadows an attribute in parent "ISettings"
  warnings.warn(
/home/saketh/.local/lib/python3.10/site-packages/pydantic/_internal/_fields.py:198: UserWarning: Field name "secret_key" in "Settings" shadows an attribute in parent "ISettings"
  warnings.warn(
/home/saketh/.local/lib/python3.10/site-packages/pydantic/_internal/_fields.py:198: UserWarning: Field name "algorithm" in "Settings" shadows an attribute in parent "ISettings"
  warnings.warn(
/home/saketh/.local/lib/python3.10/site-packages/pydantic/_internal/_fields.py:198: UserWarning: Field name "access_token_expire_minutes" in "Settings" shadows an attribute in parent "ISettings"
  warnings.warn(
/home/saketh/.local/lib/python3.10/site-packages/pydantic/_internal/_fields.py:198: UserWarning: Field name "cors_origins" in "Settings" shadows an attribute in parent "ISettings"
  warnings.warn(
/home/saketh/.local/lib/python3.10/site-packages/pydantic/_internal/_fields.py:198: UserWarning: Field name "upload_dir" in "Settings" shadows an attribute in parent "ISettings"
  warnings.warn(
/home/saketh/.local/lib/python3.10/site-packages/pydantic/_internal/_fields.py:198: UserWarning: Field name "max_upload_size" in "Settings" shadows an attribute in parent "ISettings"
  warnings.warn(
/home/saketh/.local/lib/python3.10/site-packages/pydantic/_internal/_fields.py:198: UserWarning: Field name "import_batch_size" in "Settings" shadows an attribute in parent "ISettings"
  warnings.warn(
/home/saketh/.local/lib/python3.10/site-packages/pydantic/_internal/_config.py:373: UserWarning: Valid config keys have changed in V2:
* 'allow_population_by_field_name' has been renamed to 'validate_by_name'
  warnings.warn(message, UserWarning)
/home/saketh/.local/lib/python3.10/site-packages/pydantic/_internal/_config.py:373: UserWarning: Valid config keys have changed in V2:
* 'schema_extra' has been renamed to 'json_schema_extra'
  warnings.warn(message, UserWarning)
INFO:src.api.error_handlers:Error handlers registered successfully
INFO:     Started server process [19419]
INFO:     Waiting for application startup.
INFO:src.main:Starting DSA Platform...
ERROR:    Traceback (most recent call last):
  File "/home/saketh/.local/lib/python3.10/site-packages/starlette/routing.py", line 692, in lifespan
    async with self.lifespan_context(app) as maybe_state:
  File "/usr/lib/python3.10/contextlib.py", line 199, in __aenter__
    return await anext(self.gen)
  File "/home/saketh/.local/lib/python3.10/site-packages/fastapi/routing.py", line 133, in merged_lifespan
    async with original_context(app) as maybe_original_state:
  File "/usr/lib/python3.10/contextlib.py", line 199, in __aenter__
    return await anext(self.gen)
  File "/home/saketh/.local/lib/python3.10/site-packages/fastapi/routing.py", line 133, in merged_lifespan
    async with original_context(app) as maybe_original_state:
  File "/usr/lib/python3.10/contextlib.py", line 199, in __aenter__
    return await anext(self.gen)
  File "/home/saketh/.local/lib/python3.10/site-packages/fastapi/routing.py", line 133, in merged_lifespan
    async with original_context(app) as maybe_original_state:
  File "/usr/lib/python3.10/contextlib.py", line 199, in __aenter__
    return await anext(self.gen)
  File "/home/saketh/.local/lib/python3.10/site-packages/fastapi/routing.py", line 133, in merged_lifespan
    async with original_context(app) as maybe_original_state:
  File "/usr/lib/python3.10/contextlib.py", line 199, in __aenter__
    return await anext(self.gen)
  File "/home/saketh/.local/lib/python3.10/site-packages/fastapi/routing.py", line 133, in merged_lifespan
    async with original_context(app) as maybe_original_state:
  File "/usr/lib/python3.10/contextlib.py", line 199, in __aenter__
    return await anext(self.gen)
  File "/home/saketh/.local/lib/python3.10/site-packages/fastapi/routing.py", line 133, in merged_lifespan
    async with original_context(app) as maybe_original_state:
  File "/usr/lib/python3.10/contextlib.py", line 199, in __aenter__
    return await anext(self.gen)
  File "/home/saketh/.local/lib/python3.10/site-packages/fastapi/routing.py", line 133, in merged_lifespan
    async with original_context(app) as maybe_original_state:
  File "/usr/lib/python3.10/contextlib.py", line 199, in __aenter__
    return await anext(self.gen)
  File "/home/saketh/.local/lib/python3.10/site-packages/fastapi/routing.py", line 133, in merged_lifespan
    async with original_context(app) as maybe_original_state:
  File "/usr/lib/python3.10/contextlib.py", line 199, in __aenter__
    return await anext(self.gen)
  File "/home/saketh/.local/lib/python3.10/site-packages/fastapi/routing.py", line 133, in merged_lifespan
    async with original_context(app) as maybe_original_state:
  File "/usr/lib/python3.10/contextlib.py", line 199, in __aenter__
    return await anext(self.gen)
  File "/home/saketh/Projects/dsa/src/main.py", line 52, in lifespan
    await db_pool.initialize()
  File "/home/saketh/Projects/dsa/src/infrastructure/postgres/database.py", line 22, in initialize
    self._pool = await asyncpg.create_pool(
  File "/home/saketh/.local/lib/python3.10/site-packages/asyncpg/pool.py", line 418, in _async__init__
    await self._initialize()
  File "/home/saketh/.local/lib/python3.10/site-packages/asyncpg/pool.py", line 445, in _initialize
    await first_ch.connect()
  File "/home/saketh/.local/lib/python3.10/site-packages/asyncpg/pool.py", line 132, in connect
    self._con = await self._pool._get_new_connection()
  File "/home/saketh/.local/lib/python3.10/site-packages/asyncpg/pool.py", line 517, in _get_new_connection
    con = await self._connect(
  File "/home/saketh/.local/lib/python3.10/site-packages/asyncpg/connection.py", line 2421, in connect
    return await connect_utils._connect(
  File "/home/saketh/.local/lib/python3.10/site-packages/asyncpg/connect_utils.py", line 1049, in _connect
    conn = await _connect_addr(
  File "/home/saketh/.local/lib/python3.10/site-packages/asyncpg/connect_utils.py", line 886, in _connect_addr
    return await __connect_addr(params, True, *args)
  File "/home/saketh/.local/lib/python3.10/site-packages/asyncpg/connect_utils.py", line 934, in __connect_addr
    await connected
asyncpg.exceptions.InvalidPasswordError: password authentication failed for user "saketh"

ERROR:    Application startup failed. Exiting.
[1;34mUpgrade to ydata-sdk[0m
Improve your data and profiling with ydata-sdk, featuring data quality scoring, redundancy detection, outlier identification, text validation, and synthetic data generation.
Register at https://ydata.ai/register
WARNING:  WatchFiles detected changes in 'src/infrastructure/config/settings.py'. Reloading...
/home/saketh/.local/lib/python3.10/site-packages/pydantic/_internal/_config.py:373: UserWarning: Valid config keys have changed in V2:
* 'allow_population_by_field_name' has been renamed to 'validate_by_name'
  warnings.warn(message, UserWarning)
/home/saketh/.local/lib/python3.10/site-packages/pydantic/_internal/_config.py:373: UserWarning: Valid config keys have changed in V2:
* 'schema_extra' has been renamed to 'json_schema_extra'
  warnings.warn(message, UserWarning)
INFO:src.api.error_handlers:Error handlers registered successfully
INFO:     Started server process [19525]
INFO:     Waiting for application startup.
INFO:src.main:Starting DSA Platform...
INFO:src.main:Database pool initialized
ERROR:    Traceback (most recent call last):
  File "/home/saketh/.local/lib/python3.10/site-packages/starlette/routing.py", line 692, in lifespan
    async with self.lifespan_context(app) as maybe_state:
  File "/usr/lib/python3.10/contextlib.py", line 199, in __aenter__
    return await anext(self.gen)
  File "/home/saketh/.local/lib/python3.10/site-packages/fastapi/routing.py", line 133, in merged_lifespan
    async with original_context(app) as maybe_original_state:
  File "/usr/lib/python3.10/contextlib.py", line 199, in __aenter__
    return await anext(self.gen)
  File "/home/saketh/.local/lib/python3.10/site-packages/fastapi/routing.py", line 133, in merged_lifespan
    async with original_context(app) as maybe_original_state:
  File "/usr/lib/python3.10/contextlib.py", line 199, in __aenter__
    return await anext(self.gen)
  File "/home/saketh/.local/lib/python3.10/site-packages/fastapi/routing.py", line 133, in merged_lifespan
    async with original_context(app) as maybe_original_state:
  File "/usr/lib/python3.10/contextlib.py", line 199, in __aenter__
    return await anext(self.gen)
  File "/home/saketh/.local/lib/python3.10/site-packages/fastapi/routing.py", line 133, in merged_lifespan
    async with original_context(app) as maybe_original_state:
  File "/usr/lib/python3.10/contextlib.py", line 199, in __aenter__
    return await anext(self.gen)
  File "/home/saketh/.local/lib/python3.10/site-packages/fastapi/routing.py", line 133, in merged_lifespan
    async with original_context(app) as maybe_original_state:
  File "/usr/lib/python3.10/contextlib.py", line 199, in __aenter__
    return await anext(self.gen)
  File "/home/saketh/.local/lib/python3.10/site-packages/fastapi/routing.py", line 133, in merged_lifespan
    async with original_context(app) as maybe_original_state:
  File "/usr/lib/python3.10/contextlib.py", line 199, in __aenter__
    return await anext(self.gen)
  File "/home/saketh/.local/lib/python3.10/site-packages/fastapi/routing.py", line 133, in merged_lifespan
    async with original_context(app) as maybe_original_state:
  File "/usr/lib/python3.10/contextlib.py", line 199, in __aenter__
    return await anext(self.gen)
  File "/home/saketh/.local/lib/python3.10/site-packages/fastapi/routing.py", line 133, in merged_lifespan
    async with original_context(app) as maybe_original_state:
  File "/usr/lib/python3.10/contextlib.py", line 199, in __aenter__
    return await anext(self.gen)
  File "/home/saketh/.local/lib/python3.10/site-packages/fastapi/routing.py", line 133, in merged_lifespan
    async with original_context(app) as maybe_original_state:
  File "/usr/lib/python3.10/contextlib.py", line 199, in __aenter__
    return await anext(self.gen)
  File "/home/saketh/Projects/dsa/src/main.py", line 62, in lifespan
    'import': ImportJobExecutor(db_pool),
TypeError: ImportJobExecutor.__init__() takes 1 positional argument but 2 were given

ERROR:    Application startup failed. Exiting.
[1;34mUpgrade to ydata-sdk[0m
Improve your data and profiling with ydata-sdk, featuring data quality scoring, redundancy detection, outlier identification, text validation, and synthetic data generation.
Register at https://ydata.ai/register
WARNING:  WatchFiles detected changes in 'src/main.py'. Reloading...
/home/saketh/.local/lib/python3.10/site-packages/pydantic/_internal/_config.py:373: UserWarning: Valid config keys have changed in V2:
* 'allow_population_by_field_name' has been renamed to 'validate_by_name'
  warnings.warn(message, UserWarning)
/home/saketh/.local/lib/python3.10/site-packages/pydantic/_internal/_config.py:373: UserWarning: Valid config keys have changed in V2:
* 'schema_extra' has been renamed to 'json_schema_extra'
  warnings.warn(message, UserWarning)
INFO:src.api.error_handlers:Error handlers registered successfully
INFO:     Started server process [19633]
INFO:     Waiting for application startup.
INFO:src.main:Starting DSA Platform...
INFO:src.main:Database pool initialized
ERROR:    Traceback (most recent call last):
  File "/home/saketh/.local/lib/python3.10/site-packages/starlette/routing.py", line 692, in lifespan
    async with self.lifespan_context(app) as maybe_state:
  File "/usr/lib/python3.10/contextlib.py", line 199, in __aenter__
    return await anext(self.gen)
  File "/home/saketh/.local/lib/python3.10/site-packages/fastapi/routing.py", line 133, in merged_lifespan
    async with original_context(app) as maybe_original_state:
  File "/usr/lib/python3.10/contextlib.py", line 199, in __aenter__
    return await anext(self.gen)
  File "/home/saketh/.local/lib/python3.10/site-packages/fastapi/routing.py", line 133, in merged_lifespan
    async with original_context(app) as maybe_original_state:
  File "/usr/lib/python3.10/contextlib.py", line 199, in __aenter__
    return await anext(self.gen)
  File "/home/saketh/.local/lib/python3.10/site-packages/fastapi/routing.py", line 133, in merged_lifespan
    async with original_context(app) as maybe_original_state:
  File "/usr/lib/python3.10/contextlib.py", line 199, in __aenter__
    return await anext(self.gen)
  File "/home/saketh/.local/lib/python3.10/site-packages/fastapi/routing.py", line 133, in merged_lifespan
    async with original_context(app) as maybe_original_state:
  File "/usr/lib/python3.10/contextlib.py", line 199, in __aenter__
    return await anext(self.gen)
  File "/home/saketh/.local/lib/python3.10/site-packages/fastapi/routing.py", line 133, in merged_lifespan
    async with original_context(app) as maybe_original_state:
  File "/usr/lib/python3.10/contextlib.py", line 199, in __aenter__
    return await anext(self.gen)
  File "/home/saketh/.local/lib/python3.10/site-packages/fastapi/routing.py", line 133, in merged_lifespan
    async with original_context(app) as maybe_original_state:
  File "/usr/lib/python3.10/contextlib.py", line 199, in __aenter__
    return await anext(self.gen)
  File "/home/saketh/.local/lib/python3.10/site-packages/fastapi/routing.py", line 133, in merged_lifespan
    async with original_context(app) as maybe_original_state:
  File "/usr/lib/python3.10/contextlib.py", line 199, in __aenter__
    return await anext(self.gen)
  File "/home/saketh/.local/lib/python3.10/site-packages/fastapi/routing.py", line 133, in merged_lifespan
    async with original_context(app) as maybe_original_state:
  File "/usr/lib/python3.10/contextlib.py", line 199, in __aenter__
    return await anext(self.gen)
  File "/home/saketh/.local/lib/python3.10/site-packages/fastapi/routing.py", line 133, in merged_lifespan
    async with original_context(app) as maybe_original_state:
  File "/usr/lib/python3.10/contextlib.py", line 199, in __aenter__
    return await anext(self.gen)
  File "/home/saketh/Projects/dsa/src/main.py", line 64, in lifespan
    'exploration': ExplorationExecutor(),
TypeError: ExplorationExecutor.__init__() missing 1 required positional argument: 'pool'

ERROR:    Application startup failed. Exiting.
[1;34mUpgrade to ydata-sdk[0m
Improve your data and profiling with ydata-sdk, featuring data quality scoring, redundancy detection, outlier identification, text validation, and synthetic data generation.
Register at https://ydata.ai/register
WARNING:  WatchFiles detected changes in 'src/main.py'. Reloading...
/home/saketh/.local/lib/python3.10/site-packages/pydantic/_internal/_config.py:373: UserWarning: Valid config keys have changed in V2:
* 'allow_population_by_field_name' has been renamed to 'validate_by_name'
  warnings.warn(message, UserWarning)
/home/saketh/.local/lib/python3.10/site-packages/pydantic/_internal/_config.py:373: UserWarning: Valid config keys have changed in V2:
* 'schema_extra' has been renamed to 'json_schema_extra'
  warnings.warn(message, UserWarning)
INFO:src.api.error_handlers:Error handlers registered successfully
INFO:     Started server process [19782]
INFO:     Waiting for application startup.
INFO:src.main:Starting DSA Platform...
INFO:src.main:Database pool initialized
ERROR:    Traceback (most recent call last):
  File "/home/saketh/.local/lib/python3.10/site-packages/starlette/routing.py", line 692, in lifespan
    async with self.lifespan_context(app) as maybe_state:
  File "/usr/lib/python3.10/contextlib.py", line 199, in __aenter__
    return await anext(self.gen)
  File "/home/saketh/.local/lib/python3.10/site-packages/fastapi/routing.py", line 133, in merged_lifespan
    async with original_context(app) as maybe_original_state:
  File "/usr/lib/python3.10/contextlib.py", line 199, in __aenter__
    return await anext(self.gen)
  File "/home/saketh/.local/lib/python3.10/site-packages/fastapi/routing.py", line 133, in merged_lifespan
    async with original_context(app) as maybe_original_state:
  File "/usr/lib/python3.10/contextlib.py", line 199, in __aenter__
    return await anext(self.gen)
  File "/home/saketh/.local/lib/python3.10/site-packages/fastapi/routing.py", line 133, in merged_lifespan
    async with original_context(app) as maybe_original_state:
  File "/usr/lib/python3.10/contextlib.py", line 199, in __aenter__
    return await anext(self.gen)
  File "/home/saketh/.local/lib/python3.10/site-packages/fastapi/routing.py", line 133, in merged_lifespan
    async with original_context(app) as maybe_original_state:
  File "/usr/lib/python3.10/contextlib.py", line 199, in __aenter__
    return await anext(self.gen)
  File "/home/saketh/.local/lib/python3.10/site-packages/fastapi/routing.py", line 133, in merged_lifespan
    async with original_context(app) as maybe_original_state:
  File "/usr/lib/python3.10/contextlib.py", line 199, in __aenter__
    return await anext(self.gen)
  File "/home/saketh/.local/lib/python3.10/site-packages/fastapi/routing.py", line 133, in merged_lifespan
    async with original_context(app) as maybe_original_state:
  File "/usr/lib/python3.10/contextlib.py", line 199, in __aenter__
    return await anext(self.gen)
  File "/home/saketh/.local/lib/python3.10/site-packages/fastapi/routing.py", line 133, in merged_lifespan
    async with original_context(app) as maybe_original_state:
  File "/usr/lib/python3.10/contextlib.py", line 199, in __aenter__
    return await anext(self.gen)
  File "/home/saketh/.local/lib/python3.10/site-packages/fastapi/routing.py", line 133, in merged_lifespan
    async with original_context(app) as maybe_original_state:
  File "/usr/lib/python3.10/contextlib.py", line 199, in __aenter__
    return await anext(self.gen)
  File "/home/saketh/.local/lib/python3.10/site-packages/fastapi/routing.py", line 133, in merged_lifespan
    async with original_context(app) as maybe_original_state:
  File "/usr/lib/python3.10/contextlib.py", line 199, in __aenter__
    return await anext(self.gen)
  File "/home/saketh/Projects/dsa/src/main.py", line 68, in lifespan
    worker = JobWorker(db_pool, executors)
TypeError: JobWorker.__init__() takes 2 positional arguments but 3 were given

ERROR:    Application startup failed. Exiting.
[1;34mUpgrade to ydata-sdk[0m
Improve your data and profiling with ydata-sdk, featuring data quality scoring, redundancy detection, outlier identification, text validation, and synthetic data generation.
Register at https://ydata.ai/register
WARNING:  WatchFiles detected changes in 'src/main.py'. Reloading...
/home/saketh/.local/lib/python3.10/site-packages/pydantic/_internal/_config.py:373: UserWarning: Valid config keys have changed in V2:
* 'allow_population_by_field_name' has been renamed to 'validate_by_name'
  warnings.warn(message, UserWarning)
/home/saketh/.local/lib/python3.10/site-packages/pydantic/_internal/_config.py:373: UserWarning: Valid config keys have changed in V2:
* 'schema_extra' has been renamed to 'json_schema_extra'
  warnings.warn(message, UserWarning)
INFO:src.api.error_handlers:Error handlers registered successfully
INFO:     Started server process [19928]
INFO:     Waiting for application startup.
INFO:src.main:Starting DSA Platform...
INFO:src.main:Database pool initialized
INFO:src.workers.job_worker:Registered executor for job type: import
INFO:src.workers.job_worker:Registered executor for job type: sampling
INFO:src.workers.job_worker:Registered executor for job type: exploration
INFO:src.workers.job_worker:Registered executor for job type: sql_transform
INFO:src.main:Job worker started
INFO:src.workers.job_worker:Starting job worker...
INFO:     Application startup complete.
[1;34mUpgrade to ydata-sdk[0m
Improve your data and profiling with ydata-sdk, featuring data quality scoring, redundancy detection, outlier identification, text validation, and synthetic data generation.
Register at https://ydata.ai/register
INFO:     127.0.0.1:52694 - "GET / HTTP/1.1" 200 OK
INFO:     127.0.0.1:33582 - "POST /api/v1/users/login HTTP/1.1" 200 OK
INFO:     127.0.0.1:39514 - "GET /api/v1/datasets HTTP/1.1" 307 Temporary Redirect
ERROR:src.api.error_handlers:Unexpected error handling request 5ce14735-56ef-4eae-8fc9-44494b9bc896: Database pool not configured
  + Exception Group Traceback (most recent call last):
  |   File "/home/saketh/.local/lib/python3.10/site-packages/starlette/_utils.py", line 76, in collapse_excgroups
  |     yield
  |   File "/home/saketh/.local/lib/python3.10/site-packages/starlette/middleware/base.py", line 177, in __call__
  |     async with anyio.create_task_group() as task_group:
  |   File "/home/saketh/.local/lib/python3.10/site-packages/anyio/_backends/_asyncio.py", line 772, in __aexit__
  |     raise BaseExceptionGroup(
  | exceptiongroup.ExceptionGroup: unhandled errors in a TaskGroup (1 sub-exception)
  +-+---------------- 1 ----------------
    | Traceback (most recent call last):
    |   File "/home/saketh/.local/lib/python3.10/site-packages/starlette/middleware/errors.py", line 165, in __call__
    |     await self.app(scope, receive, _send)
    |   File "/home/saketh/.local/lib/python3.10/site-packages/starlette/middleware/base.py", line 176, in __call__
    |     with recv_stream, send_stream, collapse_excgroups():
    |   File "/usr/lib/python3.10/contextlib.py", line 153, in __exit__
    |     self.gen.throw(typ, value, traceback)
    |   File "/home/saketh/.local/lib/python3.10/site-packages/starlette/_utils.py", line 82, in collapse_excgroups
    |     raise exc
    |   File "/home/saketh/.local/lib/python3.10/site-packages/starlette/middleware/base.py", line 178, in __call__
    |     response = await self.dispatch_func(request, call_next)
    |   File "/home/saketh/Projects/dsa/src/main.py", line 148, in add_request_id
    |     response = await call_next(request)
    |   File "/home/saketh/.local/lib/python3.10/site-packages/starlette/middleware/base.py", line 156, in call_next
    |     raise app_exc
    |   File "/home/saketh/.local/lib/python3.10/site-packages/starlette/middleware/base.py", line 141, in coro
    |     await self.app(scope, receive_or_disconnect, send_no_error)
    |   File "/home/saketh/.local/lib/python3.10/site-packages/starlette/middleware/cors.py", line 85, in __call__
    |     await self.app(scope, receive, send)
    |   File "/home/saketh/.local/lib/python3.10/site-packages/starlette/middleware/exceptions.py", line 62, in __call__
    |     await wrap_app_handling_exceptions(self.app, conn)(scope, receive, send)
    |   File "/home/saketh/.local/lib/python3.10/site-packages/starlette/_exception_handler.py", line 53, in wrapped_app
    |     raise exc
    |   File "/home/saketh/.local/lib/python3.10/site-packages/starlette/_exception_handler.py", line 42, in wrapped_app
    |     await app(scope, receive, sender)
    |   File "/home/saketh/.local/lib/python3.10/site-packages/starlette/routing.py", line 714, in __call__
    |     await self.middleware_stack(scope, receive, send)
    |   File "/home/saketh/.local/lib/python3.10/site-packages/starlette/routing.py", line 734, in app
    |     await route.handle(scope, receive, send)
    |   File "/home/saketh/.local/lib/python3.10/site-packages/starlette/routing.py", line 288, in handle
    |     await self.app(scope, receive, send)
    |   File "/home/saketh/.local/lib/python3.10/site-packages/starlette/routing.py", line 76, in app
    |     await wrap_app_handling_exceptions(app, request)(scope, receive, send)
    |   File "/home/saketh/.local/lib/python3.10/site-packages/starlette/_exception_handler.py", line 53, in wrapped_app
    |     raise exc
    |   File "/home/saketh/.local/lib/python3.10/site-packages/starlette/_exception_handler.py", line 42, in wrapped_app
    |     await app(scope, receive, sender)
    |   File "/home/saketh/.local/lib/python3.10/site-packages/starlette/routing.py", line 73, in app
    |     response = await f(request)
    |   File "/home/saketh/.local/lib/python3.10/site-packages/fastapi/routing.py", line 291, in app
    |     solved_result = await solve_dependencies(
    |   File "/home/saketh/.local/lib/python3.10/site-packages/fastapi/dependencies/utils.py", line 615, in solve_dependencies
    |     solved_result = await solve_dependencies(
    |   File "/home/saketh/.local/lib/python3.10/site-packages/fastapi/dependencies/utils.py", line 640, in solve_dependencies
    |     solved = await run_in_threadpool(call, **solved_result.values)
    |   File "/home/saketh/.local/lib/python3.10/site-packages/starlette/concurrency.py", line 37, in run_in_threadpool
    |     return await anyio.to_thread.run_sync(func)
    |   File "/home/saketh/.local/lib/python3.10/site-packages/anyio/to_thread.py", line 56, in run_sync
    |     return await get_async_backend().run_sync_in_worker_thread(
    |   File "/home/saketh/.local/lib/python3.10/site-packages/anyio/_backends/_asyncio.py", line 2470, in run_sync_in_worker_thread
    |     return await future
    |   File "/home/saketh/.local/lib/python3.10/site-packages/anyio/_backends/_asyncio.py", line 967, in run
    |     result = context.run(func, *args)
    |   File "/home/saketh/Projects/dsa/src/core/authorization.py", line 15, in get_db_pool
    |     raise NotImplementedError("Database pool not configured")
    | NotImplementedError: Database pool not configured
    +------------------------------------

During handling of the above exception, another exception occurred:

Traceback (most recent call last):
  File "/home/saketh/.local/lib/python3.10/site-packages/starlette/middleware/errors.py", line 165, in __call__
    await self.app(scope, receive, _send)
  File "/home/saketh/.local/lib/python3.10/site-packages/starlette/middleware/base.py", line 176, in __call__
    with recv_stream, send_stream, collapse_excgroups():
  File "/usr/lib/python3.10/contextlib.py", line 153, in __exit__
    self.gen.throw(typ, value, traceback)
  File "/home/saketh/.local/lib/python3.10/site-packages/starlette/_utils.py", line 82, in collapse_excgroups
    raise exc
  File "/home/saketh/.local/lib/python3.10/site-packages/starlette/middleware/base.py", line 178, in __call__
    response = await self.dispatch_func(request, call_next)
  File "/home/saketh/Projects/dsa/src/main.py", line 148, in add_request_id
    response = await call_next(request)
  File "/home/saketh/.local/lib/python3.10/site-packages/starlette/middleware/base.py", line 156, in call_next
    raise app_exc
  File "/home/saketh/.local/lib/python3.10/site-packages/starlette/middleware/base.py", line 141, in coro
    await self.app(scope, receive_or_disconnect, send_no_error)
  File "/home/saketh/.local/lib/python3.10/site-packages/starlette/middleware/cors.py", line 85, in __call__
    await self.app(scope, receive, send)
  File "/home/saketh/.local/lib/python3.10/site-packages/starlette/middleware/exceptions.py", line 62, in __call__
    await wrap_app_handling_exceptions(self.app, conn)(scope, receive, send)
  File "/home/saketh/.local/lib/python3.10/site-packages/starlette/_exception_handler.py", line 53, in wrapped_app
    raise exc
  File "/home/saketh/.local/lib/python3.10/site-packages/starlette/_exception_handler.py", line 42, in wrapped_app
    await app(scope, receive, sender)
  File "/home/saketh/.local/lib/python3.10/site-packages/starlette/routing.py", line 714, in __call__
    await self.middleware_stack(scope, receive, send)
  File "/home/saketh/.local/lib/python3.10/site-packages/starlette/routing.py", line 734, in app
    await route.handle(scope, receive, send)
  File "/home/saketh/.local/lib/python3.10/site-packages/starlette/routing.py", line 288, in handle
    await self.app(scope, receive, send)
  File "/home/saketh/.local/lib/python3.10/site-packages/starlette/routing.py", line 76, in app
    await wrap_app_handling_exceptions(app, request)(scope, receive, send)
  File "/home/saketh/.local/lib/python3.10/site-packages/starlette/_exception_handler.py", line 53, in wrapped_app
    raise exc
  File "/home/saketh/.local/lib/python3.10/site-packages/starlette/_exception_handler.py", line 42, in wrapped_app
    await app(scope, receive, sender)
  File "/home/saketh/.local/lib/python3.10/site-packages/starlette/routing.py", line 73, in app
    response = await f(request)
  File "/home/saketh/.local/lib/python3.10/site-packages/fastapi/routing.py", line 291, in app
    solved_result = await solve_dependencies(
  File "/home/saketh/.local/lib/python3.10/site-packages/fastapi/dependencies/utils.py", line 615, in solve_dependencies
    solved_result = await solve_dependencies(
  File "/home/saketh/.local/lib/python3.10/site-packages/fastapi/dependencies/utils.py", line 640, in solve_dependencies
    solved = await run_in_threadpool(call, **solved_result.values)
  File "/home/saketh/.local/lib/python3.10/site-packages/starlette/concurrency.py", line 37, in run_in_threadpool
    return await anyio.to_thread.run_sync(func)
  File "/home/saketh/.local/lib/python3.10/site-packages/anyio/to_thread.py", line 56, in run_sync
    return await get_async_backend().run_sync_in_worker_thread(
  File "/home/saketh/.local/lib/python3.10/site-packages/anyio/_backends/_asyncio.py", line 2470, in run_sync_in_worker_thread
    return await future
  File "/home/saketh/.local/lib/python3.10/site-packages/anyio/_backends/_asyncio.py", line 967, in run
    result = context.run(func, *args)
  File "/home/saketh/Projects/dsa/src/core/authorization.py", line 15, in get_db_pool
    raise NotImplementedError("Database pool not configured")
NotImplementedError: Database pool not configured
INFO:     127.0.0.1:60942 - "GET /api/v1/datasets/ HTTP/1.1" 500 Internal Server Error
ERROR:    Exception in ASGI application
  + Exception Group Traceback (most recent call last):
  |   File "/home/saketh/.local/lib/python3.10/site-packages/starlette/_utils.py", line 76, in collapse_excgroups
  |     yield
  |   File "/home/saketh/.local/lib/python3.10/site-packages/starlette/middleware/base.py", line 177, in __call__
  |     async with anyio.create_task_group() as task_group:
  |   File "/home/saketh/.local/lib/python3.10/site-packages/anyio/_backends/_asyncio.py", line 772, in __aexit__
  |     raise BaseExceptionGroup(
  | exceptiongroup.ExceptionGroup: unhandled errors in a TaskGroup (1 sub-exception)
  +-+---------------- 1 ----------------
    | Traceback (most recent call last):
    |   File "/home/saketh/.local/lib/python3.10/site-packages/uvicorn/protocols/http/httptools_impl.py", line 409, in run_asgi
    |     result = await app(  # type: ignore[func-returns-value]
    |   File "/home/saketh/.local/lib/python3.10/site-packages/uvicorn/middleware/proxy_headers.py", line 60, in __call__
    |     return await self.app(scope, receive, send)
    |   File "/home/saketh/.local/lib/python3.10/site-packages/fastapi/applications.py", line 1054, in __call__
    |     await super().__call__(scope, receive, send)
    |   File "/home/saketh/.local/lib/python3.10/site-packages/starlette/applications.py", line 112, in __call__
    |     await self.middleware_stack(scope, receive, send)
    |   File "/home/saketh/.local/lib/python3.10/site-packages/starlette/middleware/errors.py", line 187, in __call__
    |     raise exc
    |   File "/home/saketh/.local/lib/python3.10/site-packages/starlette/middleware/errors.py", line 165, in __call__
    |     await self.app(scope, receive, _send)
    |   File "/home/saketh/.local/lib/python3.10/site-packages/starlette/middleware/base.py", line 176, in __call__
    |     with recv_stream, send_stream, collapse_excgroups():
    |   File "/usr/lib/python3.10/contextlib.py", line 153, in __exit__
    |     self.gen.throw(typ, value, traceback)
    |   File "/home/saketh/.local/lib/python3.10/site-packages/starlette/_utils.py", line 82, in collapse_excgroups
    |     raise exc
    |   File "/home/saketh/.local/lib/python3.10/site-packages/starlette/middleware/base.py", line 178, in __call__
    |     response = await self.dispatch_func(request, call_next)
    |   File "/home/saketh/Projects/dsa/src/main.py", line 148, in add_request_id
    |     response = await call_next(request)
    |   File "/home/saketh/.local/lib/python3.10/site-packages/starlette/middleware/base.py", line 156, in call_next
    |     raise app_exc
    |   File "/home/saketh/.local/lib/python3.10/site-packages/starlette/middleware/base.py", line 141, in coro
    |     await self.app(scope, receive_or_disconnect, send_no_error)
    |   File "/home/saketh/.local/lib/python3.10/site-packages/starlette/middleware/cors.py", line 85, in __call__
    |     await self.app(scope, receive, send)
    |   File "/home/saketh/.local/lib/python3.10/site-packages/starlette/middleware/exceptions.py", line 62, in __call__
    |     await wrap_app_handling_exceptions(self.app, conn)(scope, receive, send)
    |   File "/home/saketh/.local/lib/python3.10/site-packages/starlette/_exception_handler.py", line 53, in wrapped_app
    |     raise exc
    |   File "/home/saketh/.local/lib/python3.10/site-packages/starlette/_exception_handler.py", line 42, in wrapped_app
    |     await app(scope, receive, sender)
    |   File "/home/saketh/.local/lib/python3.10/site-packages/starlette/routing.py", line 714, in __call__
    |     await self.middleware_stack(scope, receive, send)
    |   File "/home/saketh/.local/lib/python3.10/site-packages/starlette/routing.py", line 734, in app
    |     await route.handle(scope, receive, send)
    |   File "/home/saketh/.local/lib/python3.10/site-packages/starlette/routing.py", line 288, in handle
    |     await self.app(scope, receive, send)
    |   File "/home/saketh/.local/lib/python3.10/site-packages/starlette/routing.py", line 76, in app
    |     await wrap_app_handling_exceptions(app, request)(scope, receive, send)
    |   File "/home/saketh/.local/lib/python3.10/site-packages/starlette/_exception_handler.py", line 53, in wrapped_app
    |     raise exc
    |   File "/home/saketh/.local/lib/python3.10/site-packages/starlette/_exception_handler.py", line 42, in wrapped_app
    |     await app(scope, receive, sender)
    |   File "/home/saketh/.local/lib/python3.10/site-packages/starlette/routing.py", line 73, in app
    |     response = await f(request)
    |   File "/home/saketh/.local/lib/python3.10/site-packages/fastapi/routing.py", line 291, in app
    |     solved_result = await solve_dependencies(
    |   File "/home/saketh/.local/lib/python3.10/site-packages/fastapi/dependencies/utils.py", line 615, in solve_dependencies
    |     solved_result = await solve_dependencies(
    |   File "/home/saketh/.local/lib/python3.10/site-packages/fastapi/dependencies/utils.py", line 640, in solve_dependencies
    |     solved = await run_in_threadpool(call, **solved_result.values)
    |   File "/home/saketh/.local/lib/python3.10/site-packages/starlette/concurrency.py", line 37, in run_in_threadpool
    |     return await anyio.to_thread.run_sync(func)
    |   File "/home/saketh/.local/lib/python3.10/site-packages/anyio/to_thread.py", line 56, in run_sync
    |     return await get_async_backend().run_sync_in_worker_thread(
    |   File "/home/saketh/.local/lib/python3.10/site-packages/anyio/_backends/_asyncio.py", line 2470, in run_sync_in_worker_thread
    |     return await future
    |   File "/home/saketh/.local/lib/python3.10/site-packages/anyio/_backends/_asyncio.py", line 967, in run
    |     result = context.run(func, *args)
    |   File "/home/saketh/Projects/dsa/src/core/authorization.py", line 15, in get_db_pool
    |     raise NotImplementedError("Database pool not configured")
    | NotImplementedError: Database pool not configured
    +------------------------------------

During handling of the above exception, another exception occurred:

Traceback (most recent call last):
  File "/home/saketh/.local/lib/python3.10/site-packages/uvicorn/protocols/http/httptools_impl.py", line 409, in run_asgi
    result = await app(  # type: ignore[func-returns-value]
  File "/home/saketh/.local/lib/python3.10/site-packages/uvicorn/middleware/proxy_headers.py", line 60, in __call__
    return await self.app(scope, receive, send)
  File "/home/saketh/.local/lib/python3.10/site-packages/fastapi/applications.py", line 1054, in __call__
    await super().__call__(scope, receive, send)
  File "/home/saketh/.local/lib/python3.10/site-packages/starlette/applications.py", line 112, in __call__
    await self.middleware_stack(scope, receive, send)
  File "/home/saketh/.local/lib/python3.10/site-packages/starlette/middleware/errors.py", line 187, in __call__
    raise exc
  File "/home/saketh/.local/lib/python3.10/site-packages/starlette/middleware/errors.py", line 165, in __call__
    await self.app(scope, receive, _send)
  File "/home/saketh/.local/lib/python3.10/site-packages/starlette/middleware/base.py", line 176, in __call__
    with recv_stream, send_stream, collapse_excgroups():
  File "/usr/lib/python3.10/contextlib.py", line 153, in __exit__
    self.gen.throw(typ, value, traceback)
  File "/home/saketh/.local/lib/python3.10/site-packages/starlette/_utils.py", line 82, in collapse_excgroups
    raise exc
  File "/home/saketh/.local/lib/python3.10/site-packages/starlette/middleware/base.py", line 178, in __call__
    response = await self.dispatch_func(request, call_next)
  File "/home/saketh/Projects/dsa/src/main.py", line 148, in add_request_id
    response = await call_next(request)
  File "/home/saketh/.local/lib/python3.10/site-packages/starlette/middleware/base.py", line 156, in call_next
    raise app_exc
  File "/home/saketh/.local/lib/python3.10/site-packages/starlette/middleware/base.py", line 141, in coro
    await self.app(scope, receive_or_disconnect, send_no_error)
  File "/home/saketh/.local/lib/python3.10/site-packages/starlette/middleware/cors.py", line 85, in __call__
    await self.app(scope, receive, send)
  File "/home/saketh/.local/lib/python3.10/site-packages/starlette/middleware/exceptions.py", line 62, in __call__
    await wrap_app_handling_exceptions(self.app, conn)(scope, receive, send)
  File "/home/saketh/.local/lib/python3.10/site-packages/starlette/_exception_handler.py", line 53, in wrapped_app
    raise exc
  File "/home/saketh/.local/lib/python3.10/site-packages/starlette/_exception_handler.py", line 42, in wrapped_app
    await app(scope, receive, sender)
  File "/home/saketh/.local/lib/python3.10/site-packages/starlette/routing.py", line 714, in __call__
    await self.middleware_stack(scope, receive, send)
  File "/home/saketh/.local/lib/python3.10/site-packages/starlette/routing.py", line 734, in app
    await route.handle(scope, receive, send)
  File "/home/saketh/.local/lib/python3.10/site-packages/starlette/routing.py", line 288, in handle
    await self.app(scope, receive, send)
  File "/home/saketh/.local/lib/python3.10/site-packages/starlette/routing.py", line 76, in app
    await wrap_app_handling_exceptions(app, request)(scope, receive, send)
  File "/home/saketh/.local/lib/python3.10/site-packages/starlette/_exception_handler.py", line 53, in wrapped_app
    raise exc
  File "/home/saketh/.local/lib/python3.10/site-packages/starlette/_exception_handler.py", line 42, in wrapped_app
    await app(scope, receive, sender)
  File "/home/saketh/.local/lib/python3.10/site-packages/starlette/routing.py", line 73, in app
    response = await f(request)
  File "/home/saketh/.local/lib/python3.10/site-packages/fastapi/routing.py", line 291, in app
    solved_result = await solve_dependencies(
  File "/home/saketh/.local/lib/python3.10/site-packages/fastapi/dependencies/utils.py", line 615, in solve_dependencies
    solved_result = await solve_dependencies(
  File "/home/saketh/.local/lib/python3.10/site-packages/fastapi/dependencies/utils.py", line 640, in solve_dependencies
    solved = await run_in_threadpool(call, **solved_result.values)
  File "/home/saketh/.local/lib/python3.10/site-packages/starlette/concurrency.py", line 37, in run_in_threadpool
    return await anyio.to_thread.run_sync(func)
  File "/home/saketh/.local/lib/python3.10/site-packages/anyio/to_thread.py", line 56, in run_sync
    return await get_async_backend().run_sync_in_worker_thread(
  File "/home/saketh/.local/lib/python3.10/site-packages/anyio/_backends/_asyncio.py", line 2470, in run_sync_in_worker_thread
    return await future
  File "/home/saketh/.local/lib/python3.10/site-packages/anyio/_backends/_asyncio.py", line 967, in run
    result = context.run(func, *args)
  File "/home/saketh/Projects/dsa/src/core/authorization.py", line 15, in get_db_pool
    raise NotImplementedError("Database pool not configured")
NotImplementedError: Database pool not configured
WARNING:  WatchFiles detected changes in 'src/core/authorization.py'. Reloading...
INFO:     Shutting down
INFO:     Waiting for application shutdown.
INFO:src.main:Shutting down DSA Platform...
INFO:src.workers.job_worker:Stopping job worker...
INFO:src.main:Shutdown complete
INFO:     Application shutdown complete.
INFO:     Finished server process [19928]
/home/saketh/.local/lib/python3.10/site-packages/pydantic/_internal/_config.py:373: UserWarning: Valid config keys have changed in V2:
* 'allow_population_by_field_name' has been renamed to 'validate_by_name'
  warnings.warn(message, UserWarning)
/home/saketh/.local/lib/python3.10/site-packages/pydantic/_internal/_config.py:373: UserWarning: Valid config keys have changed in V2:
* 'schema_extra' has been renamed to 'json_schema_extra'
  warnings.warn(message, UserWarning)
INFO:src.api.error_handlers:Error handlers registered successfully
INFO:     Started server process [20067]
INFO:     Waiting for application startup.
INFO:src.main:Starting DSA Platform...
INFO:src.main:Database pool initialized
INFO:src.workers.job_worker:Registered executor for job type: import
INFO:src.workers.job_worker:Registered executor for job type: sampling
INFO:src.workers.job_worker:Registered executor for job type: exploration
INFO:src.workers.job_worker:Registered executor for job type: sql_transform
INFO:src.main:Job worker started
INFO:src.workers.job_worker:Starting job worker...
INFO:     Application startup complete.
ERROR:src.api.error_handlers:Unexpected error handling request 41f8b3d7-8789-46e1-8d96-f4aaf9fed992: No module named 'src.core.infrastructure'
  + Exception Group Traceback (most recent call last):
  |   File "/home/saketh/.local/lib/python3.10/site-packages/starlette/_utils.py", line 76, in collapse_excgroups
  |     yield
  |   File "/home/saketh/.local/lib/python3.10/site-packages/starlette/middleware/base.py", line 177, in __call__
  |     async with anyio.create_task_group() as task_group:
  |   File "/home/saketh/.local/lib/python3.10/site-packages/anyio/_backends/_asyncio.py", line 772, in __aexit__
  |     raise BaseExceptionGroup(
  | exceptiongroup.ExceptionGroup: unhandled errors in a TaskGroup (1 sub-exception)
  +-+---------------- 1 ----------------
    | Traceback (most recent call last):
    |   File "/home/saketh/.local/lib/python3.10/site-packages/starlette/middleware/errors.py", line 165, in __call__
    |     await self.app(scope, receive, _send)
    |   File "/home/saketh/.local/lib/python3.10/site-packages/starlette/middleware/base.py", line 176, in __call__
    |     with recv_stream, send_stream, collapse_excgroups():
    |   File "/usr/lib/python3.10/contextlib.py", line 153, in __exit__
    |     self.gen.throw(typ, value, traceback)
    |   File "/home/saketh/.local/lib/python3.10/site-packages/starlette/_utils.py", line 82, in collapse_excgroups
    |     raise exc
    |   File "/home/saketh/.local/lib/python3.10/site-packages/starlette/middleware/base.py", line 178, in __call__
    |     response = await self.dispatch_func(request, call_next)
    |   File "/home/saketh/Projects/dsa/src/main.py", line 148, in add_request_id
    |     response = await call_next(request)
    |   File "/home/saketh/.local/lib/python3.10/site-packages/starlette/middleware/base.py", line 156, in call_next
    |     raise app_exc
    |   File "/home/saketh/.local/lib/python3.10/site-packages/starlette/middleware/base.py", line 141, in coro
    |     await self.app(scope, receive_or_disconnect, send_no_error)
    |   File "/home/saketh/.local/lib/python3.10/site-packages/starlette/middleware/cors.py", line 85, in __call__
    |     await self.app(scope, receive, send)
    |   File "/home/saketh/.local/lib/python3.10/site-packages/starlette/middleware/exceptions.py", line 62, in __call__
    |     await wrap_app_handling_exceptions(self.app, conn)(scope, receive, send)
    |   File "/home/saketh/.local/lib/python3.10/site-packages/starlette/_exception_handler.py", line 53, in wrapped_app
    |     raise exc
    |   File "/home/saketh/.local/lib/python3.10/site-packages/starlette/_exception_handler.py", line 42, in wrapped_app
    |     await app(scope, receive, sender)
    |   File "/home/saketh/.local/lib/python3.10/site-packages/starlette/routing.py", line 714, in __call__
    |     await self.middleware_stack(scope, receive, send)
    |   File "/home/saketh/.local/lib/python3.10/site-packages/starlette/routing.py", line 734, in app
    |     await route.handle(scope, receive, send)
    |   File "/home/saketh/.local/lib/python3.10/site-packages/starlette/routing.py", line 288, in handle
    |     await self.app(scope, receive, send)
    |   File "/home/saketh/.local/lib/python3.10/site-packages/starlette/routing.py", line 76, in app
    |     await wrap_app_handling_exceptions(app, request)(scope, receive, send)
    |   File "/home/saketh/.local/lib/python3.10/site-packages/starlette/_exception_handler.py", line 53, in wrapped_app
    |     raise exc
    |   File "/home/saketh/.local/lib/python3.10/site-packages/starlette/_exception_handler.py", line 42, in wrapped_app
    |     await app(scope, receive, sender)
    |   File "/home/saketh/.local/lib/python3.10/site-packages/starlette/routing.py", line 73, in app
    |     response = await f(request)
    |   File "/home/saketh/.local/lib/python3.10/site-packages/fastapi/routing.py", line 291, in app
    |     solved_result = await solve_dependencies(
    |   File "/home/saketh/.local/lib/python3.10/site-packages/fastapi/dependencies/utils.py", line 638, in solve_dependencies
    |     solved = await call(**solved_result.values)
    |   File "/home/saketh/Projects/dsa/src/core/authorization.py", line 29, in get_current_user_info
    |     from .infrastructure.postgres import PostgresUserRepository
    | ModuleNotFoundError: No module named 'src.core.infrastructure'
    +------------------------------------

During handling of the above exception, another exception occurred:

Traceback (most recent call last):
  File "/home/saketh/.local/lib/python3.10/site-packages/starlette/middleware/errors.py", line 165, in __call__
    await self.app(scope, receive, _send)
  File "/home/saketh/.local/lib/python3.10/site-packages/starlette/middleware/base.py", line 176, in __call__
    with recv_stream, send_stream, collapse_excgroups():
  File "/usr/lib/python3.10/contextlib.py", line 153, in __exit__
    self.gen.throw(typ, value, traceback)
  File "/home/saketh/.local/lib/python3.10/site-packages/starlette/_utils.py", line 82, in collapse_excgroups
    raise exc
  File "/home/saketh/.local/lib/python3.10/site-packages/starlette/middleware/base.py", line 178, in __call__
    response = await self.dispatch_func(request, call_next)
  File "/home/saketh/Projects/dsa/src/main.py", line 148, in add_request_id
    response = await call_next(request)
  File "/home/saketh/.local/lib/python3.10/site-packages/starlette/middleware/base.py", line 156, in call_next
    raise app_exc
  File "/home/saketh/.local/lib/python3.10/site-packages/starlette/middleware/base.py", line 141, in coro
    await self.app(scope, receive_or_disconnect, send_no_error)
  File "/home/saketh/.local/lib/python3.10/site-packages/starlette/middleware/cors.py", line 85, in __call__
    await self.app(scope, receive, send)
  File "/home/saketh/.local/lib/python3.10/site-packages/starlette/middleware/exceptions.py", line 62, in __call__
    await wrap_app_handling_exceptions(self.app, conn)(scope, receive, send)
  File "/home/saketh/.local/lib/python3.10/site-packages/starlette/_exception_handler.py", line 53, in wrapped_app
    raise exc
  File "/home/saketh/.local/lib/python3.10/site-packages/starlette/_exception_handler.py", line 42, in wrapped_app
    await app(scope, receive, sender)
  File "/home/saketh/.local/lib/python3.10/site-packages/starlette/routing.py", line 714, in __call__
    await self.middleware_stack(scope, receive, send)
  File "/home/saketh/.local/lib/python3.10/site-packages/starlette/routing.py", line 734, in app
    await route.handle(scope, receive, send)
  File "/home/saketh/.local/lib/python3.10/site-packages/starlette/routing.py", line 288, in handle
    await self.app(scope, receive, send)
  File "/home/saketh/.local/lib/python3.10/site-packages/starlette/routing.py", line 76, in app
    await wrap_app_handling_exceptions(app, request)(scope, receive, send)
  File "/home/saketh/.local/lib/python3.10/site-packages/starlette/_exception_handler.py", line 53, in wrapped_app
    raise exc
  File "/home/saketh/.local/lib/python3.10/site-packages/starlette/_exception_handler.py", line 42, in wrapped_app
    await app(scope, receive, sender)
  File "/home/saketh/.local/lib/python3.10/site-packages/starlette/routing.py", line 73, in app
    response = await f(request)
  File "/home/saketh/.local/lib/python3.10/site-packages/fastapi/routing.py", line 291, in app
    solved_result = await solve_dependencies(
  File "/home/saketh/.local/lib/python3.10/site-packages/fastapi/dependencies/utils.py", line 638, in solve_dependencies
    solved = await call(**solved_result.values)
  File "/home/saketh/Projects/dsa/src/core/authorization.py", line 29, in get_current_user_info
    from .infrastructure.postgres import PostgresUserRepository
ModuleNotFoundError: No module named 'src.core.infrastructure'
[1;34mUpgrade to ydata-sdk[0m
Improve your data and profiling with ydata-sdk, featuring data quality scoring, redundancy detection, outlier identification, text validation, and synthetic data generation.
Register at https://ydata.ai/register
INFO:     127.0.0.1:52630 - "GET /api/v1/datasets/ HTTP/1.1" 500 Internal Server Error
ERROR:    Exception in ASGI application
  + Exception Group Traceback (most recent call last):
  |   File "/home/saketh/.local/lib/python3.10/site-packages/starlette/_utils.py", line 76, in collapse_excgroups
  |     yield
  |   File "/home/saketh/.local/lib/python3.10/site-packages/starlette/middleware/base.py", line 177, in __call__
  |     async with anyio.create_task_group() as task_group:
  |   File "/home/saketh/.local/lib/python3.10/site-packages/anyio/_backends/_asyncio.py", line 772, in __aexit__
  |     raise BaseExceptionGroup(
  | exceptiongroup.ExceptionGroup: unhandled errors in a TaskGroup (1 sub-exception)
  +-+---------------- 1 ----------------
    | Traceback (most recent call last):
    |   File "/home/saketh/.local/lib/python3.10/site-packages/uvicorn/protocols/http/httptools_impl.py", line 409, in run_asgi
    |     result = await app(  # type: ignore[func-returns-value]
    |   File "/home/saketh/.local/lib/python3.10/site-packages/uvicorn/middleware/proxy_headers.py", line 60, in __call__
    |     return await self.app(scope, receive, send)
    |   File "/home/saketh/.local/lib/python3.10/site-packages/fastapi/applications.py", line 1054, in __call__
    |     await super().__call__(scope, receive, send)
    |   File "/home/saketh/.local/lib/python3.10/site-packages/starlette/applications.py", line 112, in __call__
    |     await self.middleware_stack(scope, receive, send)
    |   File "/home/saketh/.local/lib/python3.10/site-packages/starlette/middleware/errors.py", line 187, in __call__
    |     raise exc
    |   File "/home/saketh/.local/lib/python3.10/site-packages/starlette/middleware/errors.py", line 165, in __call__
    |     await self.app(scope, receive, _send)
    |   File "/home/saketh/.local/lib/python3.10/site-packages/starlette/middleware/base.py", line 176, in __call__
    |     with recv_stream, send_stream, collapse_excgroups():
    |   File "/usr/lib/python3.10/contextlib.py", line 153, in __exit__
    |     self.gen.throw(typ, value, traceback)
    |   File "/home/saketh/.local/lib/python3.10/site-packages/starlette/_utils.py", line 82, in collapse_excgroups
    |     raise exc
    |   File "/home/saketh/.local/lib/python3.10/site-packages/starlette/middleware/base.py", line 178, in __call__
    |     response = await self.dispatch_func(request, call_next)
    |   File "/home/saketh/Projects/dsa/src/main.py", line 148, in add_request_id
    |     response = await call_next(request)
    |   File "/home/saketh/.local/lib/python3.10/site-packages/starlette/middleware/base.py", line 156, in call_next
    |     raise app_exc
    |   File "/home/saketh/.local/lib/python3.10/site-packages/starlette/middleware/base.py", line 141, in coro
    |     await self.app(scope, receive_or_disconnect, send_no_error)
    |   File "/home/saketh/.local/lib/python3.10/site-packages/starlette/middleware/cors.py", line 85, in __call__
    |     await self.app(scope, receive, send)
    |   File "/home/saketh/.local/lib/python3.10/site-packages/starlette/middleware/exceptions.py", line 62, in __call__
    |     await wrap_app_handling_exceptions(self.app, conn)(scope, receive, send)
    |   File "/home/saketh/.local/lib/python3.10/site-packages/starlette/_exception_handler.py", line 53, in wrapped_app
    |     raise exc
    |   File "/home/saketh/.local/lib/python3.10/site-packages/starlette/_exception_handler.py", line 42, in wrapped_app
    |     await app(scope, receive, sender)
    |   File "/home/saketh/.local/lib/python3.10/site-packages/starlette/routing.py", line 714, in __call__
    |     await self.middleware_stack(scope, receive, send)
    |   File "/home/saketh/.local/lib/python3.10/site-packages/starlette/routing.py", line 734, in app
    |     await route.handle(scope, receive, send)
    |   File "/home/saketh/.local/lib/python3.10/site-packages/starlette/routing.py", line 288, in handle
    |     await self.app(scope, receive, send)
    |   File "/home/saketh/.local/lib/python3.10/site-packages/starlette/routing.py", line 76, in app
    |     await wrap_app_handling_exceptions(app, request)(scope, receive, send)
    |   File "/home/saketh/.local/lib/python3.10/site-packages/starlette/_exception_handler.py", line 53, in wrapped_app
    |     raise exc
    |   File "/home/saketh/.local/lib/python3.10/site-packages/starlette/_exception_handler.py", line 42, in wrapped_app
    |     await app(scope, receive, sender)
    |   File "/home/saketh/.local/lib/python3.10/site-packages/starlette/routing.py", line 73, in app
    |     response = await f(request)
    |   File "/home/saketh/.local/lib/python3.10/site-packages/fastapi/routing.py", line 291, in app
    |     solved_result = await solve_dependencies(
    |   File "/home/saketh/.local/lib/python3.10/site-packages/fastapi/dependencies/utils.py", line 638, in solve_dependencies
    |     solved = await call(**solved_result.values)
    |   File "/home/saketh/Projects/dsa/src/core/authorization.py", line 29, in get_current_user_info
    |     from .infrastructure.postgres import PostgresUserRepository
    | ModuleNotFoundError: No module named 'src.core.infrastructure'
    +------------------------------------

During handling of the above exception, another exception occurred:

Traceback (most recent call last):
  File "/home/saketh/.local/lib/python3.10/site-packages/uvicorn/protocols/http/httptools_impl.py", line 409, in run_asgi
    result = await app(  # type: ignore[func-returns-value]
  File "/home/saketh/.local/lib/python3.10/site-packages/uvicorn/middleware/proxy_headers.py", line 60, in __call__
    return await self.app(scope, receive, send)
  File "/home/saketh/.local/lib/python3.10/site-packages/fastapi/applications.py", line 1054, in __call__
    await super().__call__(scope, receive, send)
  File "/home/saketh/.local/lib/python3.10/site-packages/starlette/applications.py", line 112, in __call__
    await self.middleware_stack(scope, receive, send)
  File "/home/saketh/.local/lib/python3.10/site-packages/starlette/middleware/errors.py", line 187, in __call__
    raise exc
  File "/home/saketh/.local/lib/python3.10/site-packages/starlette/middleware/errors.py", line 165, in __call__
    await self.app(scope, receive, _send)
  File "/home/saketh/.local/lib/python3.10/site-packages/starlette/middleware/base.py", line 176, in __call__
    with recv_stream, send_stream, collapse_excgroups():
  File "/usr/lib/python3.10/contextlib.py", line 153, in __exit__
    self.gen.throw(typ, value, traceback)
  File "/home/saketh/.local/lib/python3.10/site-packages/starlette/_utils.py", line 82, in collapse_excgroups
    raise exc
  File "/home/saketh/.local/lib/python3.10/site-packages/starlette/middleware/base.py", line 178, in __call__
    response = await self.dispatch_func(request, call_next)
  File "/home/saketh/Projects/dsa/src/main.py", line 148, in add_request_id
    response = await call_next(request)
  File "/home/saketh/.local/lib/python3.10/site-packages/starlette/middleware/base.py", line 156, in call_next
    raise app_exc
  File "/home/saketh/.local/lib/python3.10/site-packages/starlette/middleware/base.py", line 141, in coro
    await self.app(scope, receive_or_disconnect, send_no_error)
  File "/home/saketh/.local/lib/python3.10/site-packages/starlette/middleware/cors.py", line 85, in __call__
    await self.app(scope, receive, send)
  File "/home/saketh/.local/lib/python3.10/site-packages/starlette/middleware/exceptions.py", line 62, in __call__
    await wrap_app_handling_exceptions(self.app, conn)(scope, receive, send)
  File "/home/saketh/.local/lib/python3.10/site-packages/starlette/_exception_handler.py", line 53, in wrapped_app
    raise exc
  File "/home/saketh/.local/lib/python3.10/site-packages/starlette/_exception_handler.py", line 42, in wrapped_app
    await app(scope, receive, sender)
  File "/home/saketh/.local/lib/python3.10/site-packages/starlette/routing.py", line 714, in __call__
    await self.middleware_stack(scope, receive, send)
  File "/home/saketh/.local/lib/python3.10/site-packages/starlette/routing.py", line 734, in app
    await route.handle(scope, receive, send)
  File "/home/saketh/.local/lib/python3.10/site-packages/starlette/routing.py", line 288, in handle
    await self.app(scope, receive, send)
  File "/home/saketh/.local/lib/python3.10/site-packages/starlette/routing.py", line 76, in app
    await wrap_app_handling_exceptions(app, request)(scope, receive, send)
  File "/home/saketh/.local/lib/python3.10/site-packages/starlette/_exception_handler.py", line 53, in wrapped_app
    raise exc
  File "/home/saketh/.local/lib/python3.10/site-packages/starlette/_exception_handler.py", line 42, in wrapped_app
    await app(scope, receive, sender)
  File "/home/saketh/.local/lib/python3.10/site-packages/starlette/routing.py", line 73, in app
    response = await f(request)
  File "/home/saketh/.local/lib/python3.10/site-packages/fastapi/routing.py", line 291, in app
    solved_result = await solve_dependencies(
  File "/home/saketh/.local/lib/python3.10/site-packages/fastapi/dependencies/utils.py", line 638, in solve_dependencies
    solved = await call(**solved_result.values)
  File "/home/saketh/Projects/dsa/src/core/authorization.py", line 29, in get_current_user_info
    from .infrastructure.postgres import PostgresUserRepository
ModuleNotFoundError: No module named 'src.core.infrastructure'
WARNING:  WatchFiles detected changes in 'src/core/authorization.py'. Reloading...
INFO:     Shutting down
INFO:     Waiting for application shutdown.
INFO:src.main:Shutting down DSA Platform...
INFO:src.workers.job_worker:Stopping job worker...
INFO:src.main:Shutdown complete
INFO:     Application shutdown complete.
INFO:     Finished server process [20067]
/home/saketh/.local/lib/python3.10/site-packages/pydantic/_internal/_config.py:373: UserWarning: Valid config keys have changed in V2:
* 'allow_population_by_field_name' has been renamed to 'validate_by_name'
  warnings.warn(message, UserWarning)
/home/saketh/.local/lib/python3.10/site-packages/pydantic/_internal/_config.py:373: UserWarning: Valid config keys have changed in V2:
* 'schema_extra' has been renamed to 'json_schema_extra'
  warnings.warn(message, UserWarning)
INFO:src.api.error_handlers:Error handlers registered successfully
INFO:     Started server process [20177]
INFO:     Waiting for application startup.
INFO:src.main:Starting DSA Platform...
INFO:src.main:Database pool initialized
INFO:src.workers.job_worker:Registered executor for job type: import
INFO:src.workers.job_worker:Registered executor for job type: sampling
INFO:src.workers.job_worker:Registered executor for job type: exploration
INFO:src.workers.job_worker:Registered executor for job type: sql_transform
INFO:src.main:Job worker started
INFO:src.workers.job_worker:Starting job worker...
INFO:     Application startup complete.
[1;34mUpgrade to ydata-sdk[0m
Improve your data and profiling with ydata-sdk, featuring data quality scoring, redundancy detection, outlier identification, text validation, and synthetic data generation.
Register at https://ydata.ai/register
INFO:     127.0.0.1:35244 - "GET /api/v1/datasets/ HTTP/1.1" 200 OK
ERROR:src.api.error_handlers:Unexpected error handling request de529053-685d-4065-b45e-4c12577803f2: 'DatabasePool' object has no attribute '_closed'
  + Exception Group Traceback (most recent call last):
  |   File "/home/saketh/.local/lib/python3.10/site-packages/starlette/_utils.py", line 76, in collapse_excgroups
  |     yield
  |   File "/home/saketh/.local/lib/python3.10/site-packages/starlette/middleware/base.py", line 177, in __call__
  |     async with anyio.create_task_group() as task_group:
  |   File "/home/saketh/.local/lib/python3.10/site-packages/anyio/_backends/_asyncio.py", line 772, in __aexit__
  |     raise BaseExceptionGroup(
  | exceptiongroup.ExceptionGroup: unhandled errors in a TaskGroup (1 sub-exception)
  +-+---------------- 1 ----------------
    | Traceback (most recent call last):
    |   File "/home/saketh/.local/lib/python3.10/site-packages/starlette/middleware/errors.py", line 165, in __call__
    |     await self.app(scope, receive, _send)
    |   File "/home/saketh/.local/lib/python3.10/site-packages/starlette/middleware/base.py", line 176, in __call__
    |     with recv_stream, send_stream, collapse_excgroups():
    |   File "/usr/lib/python3.10/contextlib.py", line 153, in __exit__
    |     self.gen.throw(typ, value, traceback)
    |   File "/home/saketh/.local/lib/python3.10/site-packages/starlette/_utils.py", line 82, in collapse_excgroups
    |     raise exc
    |   File "/home/saketh/.local/lib/python3.10/site-packages/starlette/middleware/base.py", line 178, in __call__
    |     response = await self.dispatch_func(request, call_next)
    |   File "/home/saketh/Projects/dsa/src/main.py", line 148, in add_request_id
    |     response = await call_next(request)
    |   File "/home/saketh/.local/lib/python3.10/site-packages/starlette/middleware/base.py", line 156, in call_next
    |     raise app_exc
    |   File "/home/saketh/.local/lib/python3.10/site-packages/starlette/middleware/base.py", line 141, in coro
    |     await self.app(scope, receive_or_disconnect, send_no_error)
    |   File "/home/saketh/.local/lib/python3.10/site-packages/starlette/middleware/cors.py", line 85, in __call__
    |     await self.app(scope, receive, send)
    |   File "/home/saketh/.local/lib/python3.10/site-packages/starlette/middleware/exceptions.py", line 62, in __call__
    |     await wrap_app_handling_exceptions(self.app, conn)(scope, receive, send)
    |   File "/home/saketh/.local/lib/python3.10/site-packages/starlette/_exception_handler.py", line 53, in wrapped_app
    |     raise exc
    |   File "/home/saketh/.local/lib/python3.10/site-packages/starlette/_exception_handler.py", line 42, in wrapped_app
    |     await app(scope, receive, sender)
    |   File "/home/saketh/.local/lib/python3.10/site-packages/starlette/routing.py", line 714, in __call__
    |     await self.middleware_stack(scope, receive, send)
    |   File "/home/saketh/.local/lib/python3.10/site-packages/starlette/routing.py", line 734, in app
    |     await route.handle(scope, receive, send)
    |   File "/home/saketh/.local/lib/python3.10/site-packages/starlette/routing.py", line 288, in handle
    |     await self.app(scope, receive, send)
    |   File "/home/saketh/.local/lib/python3.10/site-packages/starlette/routing.py", line 76, in app
    |     await wrap_app_handling_exceptions(app, request)(scope, receive, send)
    |   File "/home/saketh/.local/lib/python3.10/site-packages/starlette/_exception_handler.py", line 53, in wrapped_app
    |     raise exc
    |   File "/home/saketh/.local/lib/python3.10/site-packages/starlette/_exception_handler.py", line 42, in wrapped_app
    |     await app(scope, receive, sender)
    |   File "/home/saketh/.local/lib/python3.10/site-packages/starlette/routing.py", line 73, in app
    |     response = await f(request)
    |   File "/home/saketh/.local/lib/python3.10/site-packages/fastapi/routing.py", line 301, in app
    |     raw_response = await run_endpoint_function(
    |   File "/home/saketh/.local/lib/python3.10/site-packages/fastapi/routing.py", line 212, in run_endpoint_function
    |     return await dependant.call(**values)
    |   File "/home/saketh/Projects/dsa/src/main.py", line 135, in health
    |     "database": "connected" if db_pool and not db_pool._closed else "disconnected",
    | AttributeError: 'DatabasePool' object has no attribute '_closed'. Did you mean: 'close'?
    +------------------------------------

During handling of the above exception, another exception occurred:

Traceback (most recent call last):
  File "/home/saketh/.local/lib/python3.10/site-packages/starlette/middleware/errors.py", line 165, in __call__
    await self.app(scope, receive, _send)
  File "/home/saketh/.local/lib/python3.10/site-packages/starlette/middleware/base.py", line 176, in __call__
    with recv_stream, send_stream, collapse_excgroups():
  File "/usr/lib/python3.10/contextlib.py", line 153, in __exit__
    self.gen.throw(typ, value, traceback)
  File "/home/saketh/.local/lib/python3.10/site-packages/starlette/_utils.py", line 82, in collapse_excgroups
    raise exc
  File "/home/saketh/.local/lib/python3.10/site-packages/starlette/middleware/base.py", line 178, in __call__
    response = await self.dispatch_func(request, call_next)
  File "/home/saketh/Projects/dsa/src/main.py", line 148, in add_request_id
    response = await call_next(request)
  File "/home/saketh/.local/lib/python3.10/site-packages/starlette/middleware/base.py", line 156, in call_next
    raise app_exc
  File "/home/saketh/.local/lib/python3.10/site-packages/starlette/middleware/base.py", line 141, in coro
    await self.app(scope, receive_or_disconnect, send_no_error)
  File "/home/saketh/.local/lib/python3.10/site-packages/starlette/middleware/cors.py", line 85, in __call__
    await self.app(scope, receive, send)
  File "/home/saketh/.local/lib/python3.10/site-packages/starlette/middleware/exceptions.py", line 62, in __call__
    await wrap_app_handling_exceptions(self.app, conn)(scope, receive, send)
  File "/home/saketh/.local/lib/python3.10/site-packages/starlette/_exception_handler.py", line 53, in wrapped_app
    raise exc
  File "/home/saketh/.local/lib/python3.10/site-packages/starlette/_exception_handler.py", line 42, in wrapped_app
    await app(scope, receive, sender)
  File "/home/saketh/.local/lib/python3.10/site-packages/starlette/routing.py", line 714, in __call__
    await self.middleware_stack(scope, receive, send)
  File "/home/saketh/.local/lib/python3.10/site-packages/starlette/routing.py", line 734, in app
    await route.handle(scope, receive, send)
  File "/home/saketh/.local/lib/python3.10/site-packages/starlette/routing.py", line 288, in handle
    await self.app(scope, receive, send)
  File "/home/saketh/.local/lib/python3.10/site-packages/starlette/routing.py", line 76, in app
    await wrap_app_handling_exceptions(app, request)(scope, receive, send)
  File "/home/saketh/.local/lib/python3.10/site-packages/starlette/_exception_handler.py", line 53, in wrapped_app
    raise exc
  File "/home/saketh/.local/lib/python3.10/site-packages/starlette/_exception_handler.py", line 42, in wrapped_app
    await app(scope, receive, sender)
  File "/home/saketh/.local/lib/python3.10/site-packages/starlette/routing.py", line 73, in app
    response = await f(request)
  File "/home/saketh/.local/lib/python3.10/site-packages/fastapi/routing.py", line 301, in app
    raw_response = await run_endpoint_function(
  File "/home/saketh/.local/lib/python3.10/site-packages/fastapi/routing.py", line 212, in run_endpoint_function
    return await dependant.call(**values)
  File "/home/saketh/Projects/dsa/src/main.py", line 135, in health
    "database": "connected" if db_pool and not db_pool._closed else "disconnected",
AttributeError: 'DatabasePool' object has no attribute '_closed'. Did you mean: 'close'?
INFO:     127.0.0.1:33352 - "GET /health HTTP/1.1" 500 Internal Server Error
ERROR:    Exception in ASGI application
  + Exception Group Traceback (most recent call last):
  |   File "/home/saketh/.local/lib/python3.10/site-packages/starlette/_utils.py", line 76, in collapse_excgroups
  |     yield
  |   File "/home/saketh/.local/lib/python3.10/site-packages/starlette/middleware/base.py", line 177, in __call__
  |     async with anyio.create_task_group() as task_group:
  |   File "/home/saketh/.local/lib/python3.10/site-packages/anyio/_backends/_asyncio.py", line 772, in __aexit__
  |     raise BaseExceptionGroup(
  | exceptiongroup.ExceptionGroup: unhandled errors in a TaskGroup (1 sub-exception)
  +-+---------------- 1 ----------------
    | Traceback (most recent call last):
    |   File "/home/saketh/.local/lib/python3.10/site-packages/uvicorn/protocols/http/httptools_impl.py", line 409, in run_asgi
    |     result = await app(  # type: ignore[func-returns-value]
    |   File "/home/saketh/.local/lib/python3.10/site-packages/uvicorn/middleware/proxy_headers.py", line 60, in __call__
    |     return await self.app(scope, receive, send)
    |   File "/home/saketh/.local/lib/python3.10/site-packages/fastapi/applications.py", line 1054, in __call__
    |     await super().__call__(scope, receive, send)
    |   File "/home/saketh/.local/lib/python3.10/site-packages/starlette/applications.py", line 112, in __call__
    |     await self.middleware_stack(scope, receive, send)
    |   File "/home/saketh/.local/lib/python3.10/site-packages/starlette/middleware/errors.py", line 187, in __call__
    |     raise exc
    |   File "/home/saketh/.local/lib/python3.10/site-packages/starlette/middleware/errors.py", line 165, in __call__
    |     await self.app(scope, receive, _send)
    |   File "/home/saketh/.local/lib/python3.10/site-packages/starlette/middleware/base.py", line 176, in __call__
    |     with recv_stream, send_stream, collapse_excgroups():
    |   File "/usr/lib/python3.10/contextlib.py", line 153, in __exit__
    |     self.gen.throw(typ, value, traceback)
    |   File "/home/saketh/.local/lib/python3.10/site-packages/starlette/_utils.py", line 82, in collapse_excgroups
    |     raise exc
    |   File "/home/saketh/.local/lib/python3.10/site-packages/starlette/middleware/base.py", line 178, in __call__
    |     response = await self.dispatch_func(request, call_next)
    |   File "/home/saketh/Projects/dsa/src/main.py", line 148, in add_request_id
    |     response = await call_next(request)
    |   File "/home/saketh/.local/lib/python3.10/site-packages/starlette/middleware/base.py", line 156, in call_next
    |     raise app_exc
    |   File "/home/saketh/.local/lib/python3.10/site-packages/starlette/middleware/base.py", line 141, in coro
    |     await self.app(scope, receive_or_disconnect, send_no_error)
    |   File "/home/saketh/.local/lib/python3.10/site-packages/starlette/middleware/cors.py", line 85, in __call__
    |     await self.app(scope, receive, send)
    |   File "/home/saketh/.local/lib/python3.10/site-packages/starlette/middleware/exceptions.py", line 62, in __call__
    |     await wrap_app_handling_exceptions(self.app, conn)(scope, receive, send)
    |   File "/home/saketh/.local/lib/python3.10/site-packages/starlette/_exception_handler.py", line 53, in wrapped_app
    |     raise exc
    |   File "/home/saketh/.local/lib/python3.10/site-packages/starlette/_exception_handler.py", line 42, in wrapped_app
    |     await app(scope, receive, sender)
    |   File "/home/saketh/.local/lib/python3.10/site-packages/starlette/routing.py", line 714, in __call__
    |     await self.middleware_stack(scope, receive, send)
    |   File "/home/saketh/.local/lib/python3.10/site-packages/starlette/routing.py", line 734, in app
    |     await route.handle(scope, receive, send)
    |   File "/home/saketh/.local/lib/python3.10/site-packages/starlette/routing.py", line 288, in handle
    |     await self.app(scope, receive, send)
    |   File "/home/saketh/.local/lib/python3.10/site-packages/starlette/routing.py", line 76, in app
    |     await wrap_app_handling_exceptions(app, request)(scope, receive, send)
    |   File "/home/saketh/.local/lib/python3.10/site-packages/starlette/_exception_handler.py", line 53, in wrapped_app
    |     raise exc
    |   File "/home/saketh/.local/lib/python3.10/site-packages/starlette/_exception_handler.py", line 42, in wrapped_app
    |     await app(scope, receive, sender)
    |   File "/home/saketh/.local/lib/python3.10/site-packages/starlette/routing.py", line 73, in app
    |     response = await f(request)
    |   File "/home/saketh/.local/lib/python3.10/site-packages/fastapi/routing.py", line 301, in app
    |     raw_response = await run_endpoint_function(
    |   File "/home/saketh/.local/lib/python3.10/site-packages/fastapi/routing.py", line 212, in run_endpoint_function
    |     return await dependant.call(**values)
    |   File "/home/saketh/Projects/dsa/src/main.py", line 135, in health
    |     "database": "connected" if db_pool and not db_pool._closed else "disconnected",
    | AttributeError: 'DatabasePool' object has no attribute '_closed'. Did you mean: 'close'?
    +------------------------------------

During handling of the above exception, another exception occurred:

Traceback (most recent call last):
  File "/home/saketh/.local/lib/python3.10/site-packages/uvicorn/protocols/http/httptools_impl.py", line 409, in run_asgi
    result = await app(  # type: ignore[func-returns-value]
  File "/home/saketh/.local/lib/python3.10/site-packages/uvicorn/middleware/proxy_headers.py", line 60, in __call__
    return await self.app(scope, receive, send)
  File "/home/saketh/.local/lib/python3.10/site-packages/fastapi/applications.py", line 1054, in __call__
    await super().__call__(scope, receive, send)
  File "/home/saketh/.local/lib/python3.10/site-packages/starlette/applications.py", line 112, in __call__
    await self.middleware_stack(scope, receive, send)
  File "/home/saketh/.local/lib/python3.10/site-packages/starlette/middleware/errors.py", line 187, in __call__
    raise exc
  File "/home/saketh/.local/lib/python3.10/site-packages/starlette/middleware/errors.py", line 165, in __call__
    await self.app(scope, receive, _send)
  File "/home/saketh/.local/lib/python3.10/site-packages/starlette/middleware/base.py", line 176, in __call__
    with recv_stream, send_stream, collapse_excgroups():
  File "/usr/lib/python3.10/contextlib.py", line 153, in __exit__
    self.gen.throw(typ, value, traceback)
  File "/home/saketh/.local/lib/python3.10/site-packages/starlette/_utils.py", line 82, in collapse_excgroups
    raise exc
  File "/home/saketh/.local/lib/python3.10/site-packages/starlette/middleware/base.py", line 178, in __call__
    response = await self.dispatch_func(request, call_next)
  File "/home/saketh/Projects/dsa/src/main.py", line 148, in add_request_id
    response = await call_next(request)
  File "/home/saketh/.local/lib/python3.10/site-packages/starlette/middleware/base.py", line 156, in call_next
    raise app_exc
  File "/home/saketh/.local/lib/python3.10/site-packages/starlette/middleware/base.py", line 141, in coro
    await self.app(scope, receive_or_disconnect, send_no_error)
  File "/home/saketh/.local/lib/python3.10/site-packages/starlette/middleware/cors.py", line 85, in __call__
    await self.app(scope, receive, send)
  File "/home/saketh/.local/lib/python3.10/site-packages/starlette/middleware/exceptions.py", line 62, in __call__
    await wrap_app_handling_exceptions(self.app, conn)(scope, receive, send)
  File "/home/saketh/.local/lib/python3.10/site-packages/starlette/_exception_handler.py", line 53, in wrapped_app
    raise exc
  File "/home/saketh/.local/lib/python3.10/site-packages/starlette/_exception_handler.py", line 42, in wrapped_app
    await app(scope, receive, sender)
  File "/home/saketh/.local/lib/python3.10/site-packages/starlette/routing.py", line 714, in __call__
    await self.middleware_stack(scope, receive, send)
  File "/home/saketh/.local/lib/python3.10/site-packages/starlette/routing.py", line 734, in app
    await route.handle(scope, receive, send)
  File "/home/saketh/.local/lib/python3.10/site-packages/starlette/routing.py", line 288, in handle
    await self.app(scope, receive, send)
  File "/home/saketh/.local/lib/python3.10/site-packages/starlette/routing.py", line 76, in app
    await wrap_app_handling_exceptions(app, request)(scope, receive, send)
  File "/home/saketh/.local/lib/python3.10/site-packages/starlette/_exception_handler.py", line 53, in wrapped_app
    raise exc
  File "/home/saketh/.local/lib/python3.10/site-packages/starlette/_exception_handler.py", line 42, in wrapped_app
    await app(scope, receive, sender)
  File "/home/saketh/.local/lib/python3.10/site-packages/starlette/routing.py", line 73, in app
    response = await f(request)
  File "/home/saketh/.local/lib/python3.10/site-packages/fastapi/routing.py", line 301, in app
    raw_response = await run_endpoint_function(
  File "/home/saketh/.local/lib/python3.10/site-packages/fastapi/routing.py", line 212, in run_endpoint_function
    return await dependant.call(**values)
  File "/home/saketh/Projects/dsa/src/main.py", line 135, in health
    "database": "connected" if db_pool and not db_pool._closed else "disconnected",
AttributeError: 'DatabasePool' object has no attribute '_closed'. Did you mean: 'close'?
WARNING:  WatchFiles detected changes in 'src/main.py'. Reloading...
INFO:     Shutting down
INFO:     Waiting for application shutdown.
INFO:src.main:Shutting down DSA Platform...
INFO:src.workers.job_worker:Stopping job worker...
INFO:src.main:Shutdown complete
INFO:     Application shutdown complete.
INFO:     Finished server process [20177]
/home/saketh/.local/lib/python3.10/site-packages/pydantic/_internal/_config.py:373: UserWarning: Valid config keys have changed in V2:
* 'allow_population_by_field_name' has been renamed to 'validate_by_name'
  warnings.warn(message, UserWarning)
/home/saketh/.local/lib/python3.10/site-packages/pydantic/_internal/_config.py:373: UserWarning: Valid config keys have changed in V2:
* 'schema_extra' has been renamed to 'json_schema_extra'
  warnings.warn(message, UserWarning)
INFO:src.api.error_handlers:Error handlers registered successfully
INFO:     Started server process [20293]
INFO:     Waiting for application startup.
INFO:src.main:Starting DSA Platform...
INFO:src.main:Database pool initialized
INFO:src.workers.job_worker:Registered executor for job type: import
INFO:src.workers.job_worker:Registered executor for job type: sampling
INFO:src.workers.job_worker:Registered executor for job type: exploration
INFO:src.workers.job_worker:Registered executor for job type: sql_transform
INFO:src.main:Job worker started
INFO:src.workers.job_worker:Starting job worker...
INFO:     Application startup complete.
WARNING:  WatchFiles detected changes in 'src/main.py'. Reloading...
INFO:     Shutting down
INFO:     Waiting for application shutdown.
INFO:src.main:Shutting down DSA Platform...
INFO:src.workers.job_worker:Stopping job worker...
INFO:src.main:Shutdown complete
INFO:     Application shutdown complete.
INFO:     Finished server process [20293]
/home/saketh/.local/lib/python3.10/site-packages/pydantic/_internal/_config.py:373: UserWarning: Valid config keys have changed in V2:
* 'allow_population_by_field_name' has been renamed to 'validate_by_name'
  warnings.warn(message, UserWarning)
/home/saketh/.local/lib/python3.10/site-packages/pydantic/_internal/_config.py:373: UserWarning: Valid config keys have changed in V2:
* 'schema_extra' has been renamed to 'json_schema_extra'
  warnings.warn(message, UserWarning)
INFO:src.api.error_handlers:Error handlers registered successfully
INFO:     Started server process [20375]
INFO:     Waiting for application startup.
INFO:src.main:Starting DSA Platform...
INFO:src.main:Database pool initialized
INFO:src.workers.job_worker:Registered executor for job type: import
INFO:src.workers.job_worker:Registered executor for job type: sampling
INFO:src.workers.job_worker:Registered executor for job type: exploration
INFO:src.workers.job_worker:Registered executor for job type: sql_transform
INFO:src.main:Job worker started
INFO:src.workers.job_worker:Starting job worker...
INFO:     Application startup complete.
WARNING:  WatchFiles detected changes in 'src/main.py'. Reloading...
INFO:     Shutting down
INFO:     Waiting for application shutdown.
INFO:src.main:Shutting down DSA Platform...
INFO:src.workers.job_worker:Stopping job worker...
INFO:src.main:Shutdown complete
INFO:     Application shutdown complete.
INFO:     Finished server process [20375]
/home/saketh/.local/lib/python3.10/site-packages/pydantic/_internal/_config.py:373: UserWarning: Valid config keys have changed in V2:
* 'allow_population_by_field_name' has been renamed to 'validate_by_name'
  warnings.warn(message, UserWarning)
/home/saketh/.local/lib/python3.10/site-packages/pydantic/_internal/_config.py:373: UserWarning: Valid config keys have changed in V2:
* 'schema_extra' has been renamed to 'json_schema_extra'
  warnings.warn(message, UserWarning)
INFO:src.api.error_handlers:Error handlers registered successfully
INFO:     Started server process [20459]
INFO:     Waiting for application startup.
INFO:src.main:Starting DSA Platform...
INFO:src.main:Database pool initialized
INFO:src.workers.job_worker:Registered executor for job type: import
INFO:src.workers.job_worker:Registered executor for job type: sampling
INFO:src.workers.job_worker:Registered executor for job type: exploration
INFO:src.workers.job_worker:Registered executor for job type: sql_transform
INFO:src.main:Job worker started
INFO:src.workers.job_worker:Starting job worker...
INFO:     Application startup complete.
WARNING:  WatchFiles detected changes in 'src/main.py'. Reloading...
INFO:     Shutting down
INFO:     Waiting for application shutdown.
INFO:src.main:Shutting down DSA Platform...
INFO:src.workers.job_worker:Stopping job worker...
INFO:src.main:Shutdown complete
INFO:     Application shutdown complete.
INFO:     Finished server process [20459]
/home/saketh/.local/lib/python3.10/site-packages/pydantic/_internal/_config.py:373: UserWarning: Valid config keys have changed in V2:
* 'allow_population_by_field_name' has been renamed to 'validate_by_name'
  warnings.warn(message, UserWarning)
/home/saketh/.local/lib/python3.10/site-packages/pydantic/_internal/_config.py:373: UserWarning: Valid config keys have changed in V2:
* 'schema_extra' has been renamed to 'json_schema_extra'
  warnings.warn(message, UserWarning)
INFO:src.api.error_handlers:Error handlers registered successfully
INFO:     Started server process [20541]
INFO:     Waiting for application startup.
INFO:src.main:Starting DSA Platform...
INFO:src.main:Database pool initialized
INFO:src.workers.job_worker:Registered executor for job type: import
INFO:src.workers.job_worker:Registered executor for job type: sampling
INFO:src.workers.job_worker:Registered executor for job type: exploration
INFO:src.workers.job_worker:Registered executor for job type: sql_transform
INFO:src.main:Job worker started
INFO:src.workers.job_worker:Starting job worker...
INFO:     Application startup complete.
ERROR:src.api.error_handlers:Unexpected error handling request 1ec1f38b-d9a9-43b1-b001-73c996b798a7: 'DatabasePool' object has no attribute '_closed'
  + Exception Group Traceback (most recent call last):
  |   File "/home/saketh/.local/lib/python3.10/site-packages/starlette/_utils.py", line 76, in collapse_excgroups
  |     yield
  |   File "/home/saketh/.local/lib/python3.10/site-packages/starlette/middleware/base.py", line 177, in __call__
  |     async with anyio.create_task_group() as task_group:
  |   File "/home/saketh/.local/lib/python3.10/site-packages/anyio/_backends/_asyncio.py", line 772, in __aexit__
  |     raise BaseExceptionGroup(
  | exceptiongroup.ExceptionGroup: unhandled errors in a TaskGroup (1 sub-exception)
  +-+---------------- 1 ----------------
    | Traceback (most recent call last):
    |   File "/home/saketh/.local/lib/python3.10/site-packages/starlette/middleware/errors.py", line 165, in __call__
    |     await self.app(scope, receive, _send)
    |   File "/home/saketh/.local/lib/python3.10/site-packages/starlette/middleware/base.py", line 176, in __call__
    |     with recv_stream, send_stream, collapse_excgroups():
    |   File "/usr/lib/python3.10/contextlib.py", line 153, in __exit__
    |     self.gen.throw(typ, value, traceback)
    |   File "/home/saketh/.local/lib/python3.10/site-packages/starlette/_utils.py", line 82, in collapse_excgroups
    |     raise exc
    |   File "/home/saketh/.local/lib/python3.10/site-packages/starlette/middleware/base.py", line 178, in __call__
    |     response = await self.dispatch_func(request, call_next)
    |   File "/home/saketh/Projects/dsa/src/main.py", line 165, in add_request_id
    |     response = await call_next(request)
    |   File "/home/saketh/.local/lib/python3.10/site-packages/starlette/middleware/base.py", line 156, in call_next
    |     raise app_exc
    |   File "/home/saketh/.local/lib/python3.10/site-packages/starlette/middleware/base.py", line 141, in coro
    |     await self.app(scope, receive_or_disconnect, send_no_error)
    |   File "/home/saketh/.local/lib/python3.10/site-packages/starlette/middleware/cors.py", line 85, in __call__
    |     await self.app(scope, receive, send)
    |   File "/home/saketh/.local/lib/python3.10/site-packages/starlette/middleware/exceptions.py", line 62, in __call__
    |     await wrap_app_handling_exceptions(self.app, conn)(scope, receive, send)
    |   File "/home/saketh/.local/lib/python3.10/site-packages/starlette/_exception_handler.py", line 53, in wrapped_app
    |     raise exc
    |   File "/home/saketh/.local/lib/python3.10/site-packages/starlette/_exception_handler.py", line 42, in wrapped_app
    |     await app(scope, receive, sender)
    |   File "/home/saketh/.local/lib/python3.10/site-packages/starlette/routing.py", line 714, in __call__
    |     await self.middleware_stack(scope, receive, send)
    |   File "/home/saketh/.local/lib/python3.10/site-packages/starlette/routing.py", line 734, in app
    |     await route.handle(scope, receive, send)
    |   File "/home/saketh/.local/lib/python3.10/site-packages/starlette/routing.py", line 288, in handle
    |     await self.app(scope, receive, send)
    |   File "/home/saketh/.local/lib/python3.10/site-packages/starlette/routing.py", line 76, in app
    |     await wrap_app_handling_exceptions(app, request)(scope, receive, send)
    |   File "/home/saketh/.local/lib/python3.10/site-packages/starlette/_exception_handler.py", line 53, in wrapped_app
    |     raise exc
    |   File "/home/saketh/.local/lib/python3.10/site-packages/starlette/_exception_handler.py", line 42, in wrapped_app
    |     await app(scope, receive, sender)
    |   File "/home/saketh/.local/lib/python3.10/site-packages/starlette/routing.py", line 73, in app
    |     response = await f(request)
    |   File "/home/saketh/.local/lib/python3.10/site-packages/fastapi/routing.py", line 301, in app
    |     raw_response = await run_endpoint_function(
    |   File "/home/saketh/.local/lib/python3.10/site-packages/fastapi/routing.py", line 212, in run_endpoint_function
    |     return await dependant.call(**values)
    |   File "/home/saketh/Projects/dsa/src/main.py", line 152, in health
    |     "database": "connected" if db_pool and not db_pool._closed else "disconnected",
    | AttributeError: 'DatabasePool' object has no attribute '_closed'. Did you mean: 'close'?
    +------------------------------------

During handling of the above exception, another exception occurred:

Traceback (most recent call last):
  File "/home/saketh/.local/lib/python3.10/site-packages/starlette/middleware/errors.py", line 165, in __call__
    await self.app(scope, receive, _send)
  File "/home/saketh/.local/lib/python3.10/site-packages/starlette/middleware/base.py", line 176, in __call__
    with recv_stream, send_stream, collapse_excgroups():
  File "/usr/lib/python3.10/contextlib.py", line 153, in __exit__
    self.gen.throw(typ, value, traceback)
  File "/home/saketh/.local/lib/python3.10/site-packages/starlette/_utils.py", line 82, in collapse_excgroups
    raise exc
  File "/home/saketh/.local/lib/python3.10/site-packages/starlette/middleware/base.py", line 178, in __call__
    response = await self.dispatch_func(request, call_next)
  File "/home/saketh/Projects/dsa/src/main.py", line 165, in add_request_id
    response = await call_next(request)
  File "/home/saketh/.local/lib/python3.10/site-packages/starlette/middleware/base.py", line 156, in call_next
    raise app_exc
  File "/home/saketh/.local/lib/python3.10/site-packages/starlette/middleware/base.py", line 141, in coro
    await self.app(scope, receive_or_disconnect, send_no_error)
  File "/home/saketh/.local/lib/python3.10/site-packages/starlette/middleware/cors.py", line 85, in __call__
    await self.app(scope, receive, send)
  File "/home/saketh/.local/lib/python3.10/site-packages/starlette/middleware/exceptions.py", line 62, in __call__
    await wrap_app_handling_exceptions(self.app, conn)(scope, receive, send)
  File "/home/saketh/.local/lib/python3.10/site-packages/starlette/_exception_handler.py", line 53, in wrapped_app
    raise exc
  File "/home/saketh/.local/lib/python3.10/site-packages/starlette/_exception_handler.py", line 42, in wrapped_app
    await app(scope, receive, sender)
  File "/home/saketh/.local/lib/python3.10/site-packages/starlette/routing.py", line 714, in __call__
    await self.middleware_stack(scope, receive, send)
  File "/home/saketh/.local/lib/python3.10/site-packages/starlette/routing.py", line 734, in app
    await route.handle(scope, receive, send)
  File "/home/saketh/.local/lib/python3.10/site-packages/starlette/routing.py", line 288, in handle
    await self.app(scope, receive, send)
  File "/home/saketh/.local/lib/python3.10/site-packages/starlette/routing.py", line 76, in app
    await wrap_app_handling_exceptions(app, request)(scope, receive, send)
  File "/home/saketh/.local/lib/python3.10/site-packages/starlette/_exception_handler.py", line 53, in wrapped_app
    raise exc
  File "/home/saketh/.local/lib/python3.10/site-packages/starlette/_exception_handler.py", line 42, in wrapped_app
    await app(scope, receive, sender)
  File "/home/saketh/.local/lib/python3.10/site-packages/starlette/routing.py", line 73, in app
    response = await f(request)
  File "/home/saketh/.local/lib/python3.10/site-packages/fastapi/routing.py", line 301, in app
    raw_response = await run_endpoint_function(
  File "/home/saketh/.local/lib/python3.10/site-packages/fastapi/routing.py", line 212, in run_endpoint_function
    return await dependant.call(**values)
  File "/home/saketh/Projects/dsa/src/main.py", line 152, in health
    "database": "connected" if db_pool and not db_pool._closed else "disconnected",
AttributeError: 'DatabasePool' object has no attribute '_closed'. Did you mean: 'close'?
[1;34mUpgrade to ydata-sdk[0m
Improve your data and profiling with ydata-sdk, featuring data quality scoring, redundancy detection, outlier identification, text validation, and synthetic data generation.
Register at https://ydata.ai/register
INFO:     127.0.0.1:60828 - "GET /health HTTP/1.1" 500 Internal Server Error
ERROR:    Exception in ASGI application
  + Exception Group Traceback (most recent call last):
  |   File "/home/saketh/.local/lib/python3.10/site-packages/starlette/_utils.py", line 76, in collapse_excgroups
  |     yield
  |   File "/home/saketh/.local/lib/python3.10/site-packages/starlette/middleware/base.py", line 177, in __call__
  |     async with anyio.create_task_group() as task_group:
  |   File "/home/saketh/.local/lib/python3.10/site-packages/anyio/_backends/_asyncio.py", line 772, in __aexit__
  |     raise BaseExceptionGroup(
  | exceptiongroup.ExceptionGroup: unhandled errors in a TaskGroup (1 sub-exception)
  +-+---------------- 1 ----------------
    | Traceback (most recent call last):
    |   File "/home/saketh/.local/lib/python3.10/site-packages/uvicorn/protocols/http/httptools_impl.py", line 409, in run_asgi
    |     result = await app(  # type: ignore[func-returns-value]
    |   File "/home/saketh/.local/lib/python3.10/site-packages/uvicorn/middleware/proxy_headers.py", line 60, in __call__
    |     return await self.app(scope, receive, send)
    |   File "/home/saketh/.local/lib/python3.10/site-packages/fastapi/applications.py", line 1054, in __call__
    |     await super().__call__(scope, receive, send)
    |   File "/home/saketh/.local/lib/python3.10/site-packages/starlette/applications.py", line 112, in __call__
    |     await self.middleware_stack(scope, receive, send)
    |   File "/home/saketh/.local/lib/python3.10/site-packages/starlette/middleware/errors.py", line 187, in __call__
    |     raise exc
    |   File "/home/saketh/.local/lib/python3.10/site-packages/starlette/middleware/errors.py", line 165, in __call__
    |     await self.app(scope, receive, _send)
    |   File "/home/saketh/.local/lib/python3.10/site-packages/starlette/middleware/base.py", line 176, in __call__
    |     with recv_stream, send_stream, collapse_excgroups():
    |   File "/usr/lib/python3.10/contextlib.py", line 153, in __exit__
    |     self.gen.throw(typ, value, traceback)
    |   File "/home/saketh/.local/lib/python3.10/site-packages/starlette/_utils.py", line 82, in collapse_excgroups
    |     raise exc
    |   File "/home/saketh/.local/lib/python3.10/site-packages/starlette/middleware/base.py", line 178, in __call__
    |     response = await self.dispatch_func(request, call_next)
    |   File "/home/saketh/Projects/dsa/src/main.py", line 165, in add_request_id
    |     response = await call_next(request)
    |   File "/home/saketh/.local/lib/python3.10/site-packages/starlette/middleware/base.py", line 156, in call_next
    |     raise app_exc
    |   File "/home/saketh/.local/lib/python3.10/site-packages/starlette/middleware/base.py", line 141, in coro
    |     await self.app(scope, receive_or_disconnect, send_no_error)
    |   File "/home/saketh/.local/lib/python3.10/site-packages/starlette/middleware/cors.py", line 85, in __call__
    |     await self.app(scope, receive, send)
    |   File "/home/saketh/.local/lib/python3.10/site-packages/starlette/middleware/exceptions.py", line 62, in __call__
    |     await wrap_app_handling_exceptions(self.app, conn)(scope, receive, send)
    |   File "/home/saketh/.local/lib/python3.10/site-packages/starlette/_exception_handler.py", line 53, in wrapped_app
    |     raise exc
    |   File "/home/saketh/.local/lib/python3.10/site-packages/starlette/_exception_handler.py", line 42, in wrapped_app
    |     await app(scope, receive, sender)
    |   File "/home/saketh/.local/lib/python3.10/site-packages/starlette/routing.py", line 714, in __call__
    |     await self.middleware_stack(scope, receive, send)
    |   File "/home/saketh/.local/lib/python3.10/site-packages/starlette/routing.py", line 734, in app
    |     await route.handle(scope, receive, send)
    |   File "/home/saketh/.local/lib/python3.10/site-packages/starlette/routing.py", line 288, in handle
    |     await self.app(scope, receive, send)
    |   File "/home/saketh/.local/lib/python3.10/site-packages/starlette/routing.py", line 76, in app
    |     await wrap_app_handling_exceptions(app, request)(scope, receive, send)
    |   File "/home/saketh/.local/lib/python3.10/site-packages/starlette/_exception_handler.py", line 53, in wrapped_app
    |     raise exc
    |   File "/home/saketh/.local/lib/python3.10/site-packages/starlette/_exception_handler.py", line 42, in wrapped_app
    |     await app(scope, receive, sender)
    |   File "/home/saketh/.local/lib/python3.10/site-packages/starlette/routing.py", line 73, in app
    |     response = await f(request)
    |   File "/home/saketh/.local/lib/python3.10/site-packages/fastapi/routing.py", line 301, in app
    |     raw_response = await run_endpoint_function(
    |   File "/home/saketh/.local/lib/python3.10/site-packages/fastapi/routing.py", line 212, in run_endpoint_function
    |     return await dependant.call(**values)
    |   File "/home/saketh/Projects/dsa/src/main.py", line 152, in health
    |     "database": "connected" if db_pool and not db_pool._closed else "disconnected",
    | AttributeError: 'DatabasePool' object has no attribute '_closed'. Did you mean: 'close'?
    +------------------------------------

During handling of the above exception, another exception occurred:

Traceback (most recent call last):
  File "/home/saketh/.local/lib/python3.10/site-packages/uvicorn/protocols/http/httptools_impl.py", line 409, in run_asgi
    result = await app(  # type: ignore[func-returns-value]
  File "/home/saketh/.local/lib/python3.10/site-packages/uvicorn/middleware/proxy_headers.py", line 60, in __call__
    return await self.app(scope, receive, send)
  File "/home/saketh/.local/lib/python3.10/site-packages/fastapi/applications.py", line 1054, in __call__
    await super().__call__(scope, receive, send)
  File "/home/saketh/.local/lib/python3.10/site-packages/starlette/applications.py", line 112, in __call__
    await self.middleware_stack(scope, receive, send)
  File "/home/saketh/.local/lib/python3.10/site-packages/starlette/middleware/errors.py", line 187, in __call__
    raise exc
  File "/home/saketh/.local/lib/python3.10/site-packages/starlette/middleware/errors.py", line 165, in __call__
    await self.app(scope, receive, _send)
  File "/home/saketh/.local/lib/python3.10/site-packages/starlette/middleware/base.py", line 176, in __call__
    with recv_stream, send_stream, collapse_excgroups():
  File "/usr/lib/python3.10/contextlib.py", line 153, in __exit__
    self.gen.throw(typ, value, traceback)
  File "/home/saketh/.local/lib/python3.10/site-packages/starlette/_utils.py", line 82, in collapse_excgroups
    raise exc
  File "/home/saketh/.local/lib/python3.10/site-packages/starlette/middleware/base.py", line 178, in __call__
    response = await self.dispatch_func(request, call_next)
  File "/home/saketh/Projects/dsa/src/main.py", line 165, in add_request_id
    response = await call_next(request)
  File "/home/saketh/.local/lib/python3.10/site-packages/starlette/middleware/base.py", line 156, in call_next
    raise app_exc
  File "/home/saketh/.local/lib/python3.10/site-packages/starlette/middleware/base.py", line 141, in coro
    await self.app(scope, receive_or_disconnect, send_no_error)
  File "/home/saketh/.local/lib/python3.10/site-packages/starlette/middleware/cors.py", line 85, in __call__
    await self.app(scope, receive, send)
  File "/home/saketh/.local/lib/python3.10/site-packages/starlette/middleware/exceptions.py", line 62, in __call__
    await wrap_app_handling_exceptions(self.app, conn)(scope, receive, send)
  File "/home/saketh/.local/lib/python3.10/site-packages/starlette/_exception_handler.py", line 53, in wrapped_app
    raise exc
  File "/home/saketh/.local/lib/python3.10/site-packages/starlette/_exception_handler.py", line 42, in wrapped_app
    await app(scope, receive, sender)
  File "/home/saketh/.local/lib/python3.10/site-packages/starlette/routing.py", line 714, in __call__
    await self.middleware_stack(scope, receive, send)
  File "/home/saketh/.local/lib/python3.10/site-packages/starlette/routing.py", line 734, in app
    await route.handle(scope, receive, send)
  File "/home/saketh/.local/lib/python3.10/site-packages/starlette/routing.py", line 288, in handle
    await self.app(scope, receive, send)
  File "/home/saketh/.local/lib/python3.10/site-packages/starlette/routing.py", line 76, in app
    await wrap_app_handling_exceptions(app, request)(scope, receive, send)
  File "/home/saketh/.local/lib/python3.10/site-packages/starlette/_exception_handler.py", line 53, in wrapped_app
    raise exc
  File "/home/saketh/.local/lib/python3.10/site-packages/starlette/_exception_handler.py", line 42, in wrapped_app
    await app(scope, receive, sender)
  File "/home/saketh/.local/lib/python3.10/site-packages/starlette/routing.py", line 73, in app
    response = await f(request)
  File "/home/saketh/.local/lib/python3.10/site-packages/fastapi/routing.py", line 301, in app
    raw_response = await run_endpoint_function(
  File "/home/saketh/.local/lib/python3.10/site-packages/fastapi/routing.py", line 212, in run_endpoint_function
    return await dependant.call(**values)
  File "/home/saketh/Projects/dsa/src/main.py", line 152, in health
    "database": "connected" if db_pool and not db_pool._closed else "disconnected",
AttributeError: 'DatabasePool' object has no attribute '_closed'. Did you mean: 'close'?
INFO:     127.0.0.1:56460 - "GET /docs HTTP/1.1" 200 OK
/home/saketh/.local/lib/python3.10/site-packages/pydantic/_internal/_config.py:373: UserWarning: Valid config keys have changed in V2:
* 'allow_population_by_field_name' has been renamed to 'validate_by_name'
  warnings.warn(message, UserWarning)
INFO:     127.0.0.1:56460 - "GET /openapi.json HTTP/1.1" 200 OK
ERROR:src.api.error_handlers:Unexpected error handling request 3648a16f-ef37-44e7-beec-0006b6a417b4: 'DatabasePool' object has no attribute '_closed'
  + Exception Group Traceback (most recent call last):
  |   File "/home/saketh/.local/lib/python3.10/site-packages/starlette/_utils.py", line 76, in collapse_excgroups
  |     yield
  |   File "/home/saketh/.local/lib/python3.10/site-packages/starlette/middleware/base.py", line 177, in __call__
  |     async with anyio.create_task_group() as task_group:
  |   File "/home/saketh/.local/lib/python3.10/site-packages/anyio/_backends/_asyncio.py", line 772, in __aexit__
  |     raise BaseExceptionGroup(
  | exceptiongroup.ExceptionGroup: unhandled errors in a TaskGroup (1 sub-exception)
  +-+---------------- 1 ----------------
    | Traceback (most recent call last):
    |   File "/home/saketh/.local/lib/python3.10/site-packages/starlette/middleware/errors.py", line 165, in __call__
    |     await self.app(scope, receive, _send)
    |   File "/home/saketh/.local/lib/python3.10/site-packages/starlette/middleware/base.py", line 176, in __call__
    |     with recv_stream, send_stream, collapse_excgroups():
    |   File "/usr/lib/python3.10/contextlib.py", line 153, in __exit__
    |     self.gen.throw(typ, value, traceback)
    |   File "/home/saketh/.local/lib/python3.10/site-packages/starlette/_utils.py", line 82, in collapse_excgroups
    |     raise exc
    |   File "/home/saketh/.local/lib/python3.10/site-packages/starlette/middleware/base.py", line 178, in __call__
    |     response = await self.dispatch_func(request, call_next)
    |   File "/home/saketh/Projects/dsa/src/main.py", line 165, in add_request_id
    |     response = await call_next(request)
    |   File "/home/saketh/.local/lib/python3.10/site-packages/starlette/middleware/base.py", line 156, in call_next
    |     raise app_exc
    |   File "/home/saketh/.local/lib/python3.10/site-packages/starlette/middleware/base.py", line 141, in coro
    |     await self.app(scope, receive_or_disconnect, send_no_error)
    |   File "/home/saketh/.local/lib/python3.10/site-packages/starlette/middleware/cors.py", line 85, in __call__
    |     await self.app(scope, receive, send)
    |   File "/home/saketh/.local/lib/python3.10/site-packages/starlette/middleware/exceptions.py", line 62, in __call__
    |     await wrap_app_handling_exceptions(self.app, conn)(scope, receive, send)
    |   File "/home/saketh/.local/lib/python3.10/site-packages/starlette/_exception_handler.py", line 53, in wrapped_app
    |     raise exc
    |   File "/home/saketh/.local/lib/python3.10/site-packages/starlette/_exception_handler.py", line 42, in wrapped_app
    |     await app(scope, receive, sender)
    |   File "/home/saketh/.local/lib/python3.10/site-packages/starlette/routing.py", line 714, in __call__
    |     await self.middleware_stack(scope, receive, send)
    |   File "/home/saketh/.local/lib/python3.10/site-packages/starlette/routing.py", line 734, in app
    |     await route.handle(scope, receive, send)
    |   File "/home/saketh/.local/lib/python3.10/site-packages/starlette/routing.py", line 288, in handle
    |     await self.app(scope, receive, send)
    |   File "/home/saketh/.local/lib/python3.10/site-packages/starlette/routing.py", line 76, in app
    |     await wrap_app_handling_exceptions(app, request)(scope, receive, send)
    |   File "/home/saketh/.local/lib/python3.10/site-packages/starlette/_exception_handler.py", line 53, in wrapped_app
    |     raise exc
    |   File "/home/saketh/.local/lib/python3.10/site-packages/starlette/_exception_handler.py", line 42, in wrapped_app
    |     await app(scope, receive, sender)
    |   File "/home/saketh/.local/lib/python3.10/site-packages/starlette/routing.py", line 73, in app
    |     response = await f(request)
    |   File "/home/saketh/.local/lib/python3.10/site-packages/fastapi/routing.py", line 301, in app
    |     raw_response = await run_endpoint_function(
    |   File "/home/saketh/.local/lib/python3.10/site-packages/fastapi/routing.py", line 212, in run_endpoint_function
    |     return await dependant.call(**values)
    |   File "/home/saketh/Projects/dsa/src/main.py", line 152, in health
    |     "database": "connected" if db_pool and not db_pool._closed else "disconnected",
    | AttributeError: 'DatabasePool' object has no attribute '_closed'. Did you mean: 'close'?
    +------------------------------------

During handling of the above exception, another exception occurred:

Traceback (most recent call last):
  File "/home/saketh/.local/lib/python3.10/site-packages/starlette/middleware/errors.py", line 165, in __call__
    await self.app(scope, receive, _send)
  File "/home/saketh/.local/lib/python3.10/site-packages/starlette/middleware/base.py", line 176, in __call__
    with recv_stream, send_stream, collapse_excgroups():
  File "/usr/lib/python3.10/contextlib.py", line 153, in __exit__
    self.gen.throw(typ, value, traceback)
  File "/home/saketh/.local/lib/python3.10/site-packages/starlette/_utils.py", line 82, in collapse_excgroups
    raise exc
  File "/home/saketh/.local/lib/python3.10/site-packages/starlette/middleware/base.py", line 178, in __call__
    response = await self.dispatch_func(request, call_next)
  File "/home/saketh/Projects/dsa/src/main.py", line 165, in add_request_id
    response = await call_next(request)
  File "/home/saketh/.local/lib/python3.10/site-packages/starlette/middleware/base.py", line 156, in call_next
    raise app_exc
  File "/home/saketh/.local/lib/python3.10/site-packages/starlette/middleware/base.py", line 141, in coro
    await self.app(scope, receive_or_disconnect, send_no_error)
  File "/home/saketh/.local/lib/python3.10/site-packages/starlette/middleware/cors.py", line 85, in __call__
    await self.app(scope, receive, send)
  File "/home/saketh/.local/lib/python3.10/site-packages/starlette/middleware/exceptions.py", line 62, in __call__
    await wrap_app_handling_exceptions(self.app, conn)(scope, receive, send)
  File "/home/saketh/.local/lib/python3.10/site-packages/starlette/_exception_handler.py", line 53, in wrapped_app
    raise exc
  File "/home/saketh/.local/lib/python3.10/site-packages/starlette/_exception_handler.py", line 42, in wrapped_app
    await app(scope, receive, sender)
  File "/home/saketh/.local/lib/python3.10/site-packages/starlette/routing.py", line 714, in __call__
    await self.middleware_stack(scope, receive, send)
  File "/home/saketh/.local/lib/python3.10/site-packages/starlette/routing.py", line 734, in app
    await route.handle(scope, receive, send)
  File "/home/saketh/.local/lib/python3.10/site-packages/starlette/routing.py", line 288, in handle
    await self.app(scope, receive, send)
  File "/home/saketh/.local/lib/python3.10/site-packages/starlette/routing.py", line 76, in app
    await wrap_app_handling_exceptions(app, request)(scope, receive, send)
  File "/home/saketh/.local/lib/python3.10/site-packages/starlette/_exception_handler.py", line 53, in wrapped_app
    raise exc
  File "/home/saketh/.local/lib/python3.10/site-packages/starlette/_exception_handler.py", line 42, in wrapped_app
    await app(scope, receive, sender)
  File "/home/saketh/.local/lib/python3.10/site-packages/starlette/routing.py", line 73, in app
    response = await f(request)
  File "/home/saketh/.local/lib/python3.10/site-packages/fastapi/routing.py", line 301, in app
    raw_response = await run_endpoint_function(
  File "/home/saketh/.local/lib/python3.10/site-packages/fastapi/routing.py", line 212, in run_endpoint_function
    return await dependant.call(**values)
  File "/home/saketh/Projects/dsa/src/main.py", line 152, in health
    "database": "connected" if db_pool and not db_pool._closed else "disconnected",
AttributeError: 'DatabasePool' object has no attribute '_closed'. Did you mean: 'close'?
INFO:     127.0.0.1:47352 - "GET /health HTTP/1.1" 500 Internal Server Error
ERROR:    Exception in ASGI application
  + Exception Group Traceback (most recent call last):
  |   File "/home/saketh/.local/lib/python3.10/site-packages/starlette/_utils.py", line 76, in collapse_excgroups
  |     yield
  |   File "/home/saketh/.local/lib/python3.10/site-packages/starlette/middleware/base.py", line 177, in __call__
  |     async with anyio.create_task_group() as task_group:
  |   File "/home/saketh/.local/lib/python3.10/site-packages/anyio/_backends/_asyncio.py", line 772, in __aexit__
  |     raise BaseExceptionGroup(
  | exceptiongroup.ExceptionGroup: unhandled errors in a TaskGroup (1 sub-exception)
  +-+---------------- 1 ----------------
    | Traceback (most recent call last):
    |   File "/home/saketh/.local/lib/python3.10/site-packages/uvicorn/protocols/http/httptools_impl.py", line 409, in run_asgi
    |     result = await app(  # type: ignore[func-returns-value]
    |   File "/home/saketh/.local/lib/python3.10/site-packages/uvicorn/middleware/proxy_headers.py", line 60, in __call__
    |     return await self.app(scope, receive, send)
    |   File "/home/saketh/.local/lib/python3.10/site-packages/fastapi/applications.py", line 1054, in __call__
    |     await super().__call__(scope, receive, send)
    |   File "/home/saketh/.local/lib/python3.10/site-packages/starlette/applications.py", line 112, in __call__
    |     await self.middleware_stack(scope, receive, send)
    |   File "/home/saketh/.local/lib/python3.10/site-packages/starlette/middleware/errors.py", line 187, in __call__
    |     raise exc
    |   File "/home/saketh/.local/lib/python3.10/site-packages/starlette/middleware/errors.py", line 165, in __call__
    |     await self.app(scope, receive, _send)
    |   File "/home/saketh/.local/lib/python3.10/site-packages/starlette/middleware/base.py", line 176, in __call__
    |     with recv_stream, send_stream, collapse_excgroups():
    |   File "/usr/lib/python3.10/contextlib.py", line 153, in __exit__
    |     self.gen.throw(typ, value, traceback)
    |   File "/home/saketh/.local/lib/python3.10/site-packages/starlette/_utils.py", line 82, in collapse_excgroups
    |     raise exc
    |   File "/home/saketh/.local/lib/python3.10/site-packages/starlette/middleware/base.py", line 178, in __call__
    |     response = await self.dispatch_func(request, call_next)
    |   File "/home/saketh/Projects/dsa/src/main.py", line 165, in add_request_id
    |     response = await call_next(request)
    |   File "/home/saketh/.local/lib/python3.10/site-packages/starlette/middleware/base.py", line 156, in call_next
    |     raise app_exc
    |   File "/home/saketh/.local/lib/python3.10/site-packages/starlette/middleware/base.py", line 141, in coro
    |     await self.app(scope, receive_or_disconnect, send_no_error)
    |   File "/home/saketh/.local/lib/python3.10/site-packages/starlette/middleware/cors.py", line 85, in __call__
    |     await self.app(scope, receive, send)
    |   File "/home/saketh/.local/lib/python3.10/site-packages/starlette/middleware/exceptions.py", line 62, in __call__
    |     await wrap_app_handling_exceptions(self.app, conn)(scope, receive, send)
    |   File "/home/saketh/.local/lib/python3.10/site-packages/starlette/_exception_handler.py", line 53, in wrapped_app
    |     raise exc
    |   File "/home/saketh/.local/lib/python3.10/site-packages/starlette/_exception_handler.py", line 42, in wrapped_app
    |     await app(scope, receive, sender)
    |   File "/home/saketh/.local/lib/python3.10/site-packages/starlette/routing.py", line 714, in __call__
    |     await self.middleware_stack(scope, receive, send)
    |   File "/home/saketh/.local/lib/python3.10/site-packages/starlette/routing.py", line 734, in app
    |     await route.handle(scope, receive, send)
    |   File "/home/saketh/.local/lib/python3.10/site-packages/starlette/routing.py", line 288, in handle
    |     await self.app(scope, receive, send)
    |   File "/home/saketh/.local/lib/python3.10/site-packages/starlette/routing.py", line 76, in app
    |     await wrap_app_handling_exceptions(app, request)(scope, receive, send)
    |   File "/home/saketh/.local/lib/python3.10/site-packages/starlette/_exception_handler.py", line 53, in wrapped_app
    |     raise exc
    |   File "/home/saketh/.local/lib/python3.10/site-packages/starlette/_exception_handler.py", line 42, in wrapped_app
    |     await app(scope, receive, sender)
    |   File "/home/saketh/.local/lib/python3.10/site-packages/starlette/routing.py", line 73, in app
    |     response = await f(request)
    |   File "/home/saketh/.local/lib/python3.10/site-packages/fastapi/routing.py", line 301, in app
    |     raw_response = await run_endpoint_function(
    |   File "/home/saketh/.local/lib/python3.10/site-packages/fastapi/routing.py", line 212, in run_endpoint_function
    |     return await dependant.call(**values)
    |   File "/home/saketh/Projects/dsa/src/main.py", line 152, in health
    |     "database": "connected" if db_pool and not db_pool._closed else "disconnected",
    | AttributeError: 'DatabasePool' object has no attribute '_closed'. Did you mean: 'close'?
    +------------------------------------

During handling of the above exception, another exception occurred:

Traceback (most recent call last):
  File "/home/saketh/.local/lib/python3.10/site-packages/uvicorn/protocols/http/httptools_impl.py", line 409, in run_asgi
    result = await app(  # type: ignore[func-returns-value]
  File "/home/saketh/.local/lib/python3.10/site-packages/uvicorn/middleware/proxy_headers.py", line 60, in __call__
    return await self.app(scope, receive, send)
  File "/home/saketh/.local/lib/python3.10/site-packages/fastapi/applications.py", line 1054, in __call__
    await super().__call__(scope, receive, send)
  File "/home/saketh/.local/lib/python3.10/site-packages/starlette/applications.py", line 112, in __call__
    await self.middleware_stack(scope, receive, send)
  File "/home/saketh/.local/lib/python3.10/site-packages/starlette/middleware/errors.py", line 187, in __call__
    raise exc
  File "/home/saketh/.local/lib/python3.10/site-packages/starlette/middleware/errors.py", line 165, in __call__
    await self.app(scope, receive, _send)
  File "/home/saketh/.local/lib/python3.10/site-packages/starlette/middleware/base.py", line 176, in __call__
    with recv_stream, send_stream, collapse_excgroups():
  File "/usr/lib/python3.10/contextlib.py", line 153, in __exit__
    self.gen.throw(typ, value, traceback)
  File "/home/saketh/.local/lib/python3.10/site-packages/starlette/_utils.py", line 82, in collapse_excgroups
    raise exc
  File "/home/saketh/.local/lib/python3.10/site-packages/starlette/middleware/base.py", line 178, in __call__
    response = await self.dispatch_func(request, call_next)
  File "/home/saketh/Projects/dsa/src/main.py", line 165, in add_request_id
    response = await call_next(request)
  File "/home/saketh/.local/lib/python3.10/site-packages/starlette/middleware/base.py", line 156, in call_next
    raise app_exc
  File "/home/saketh/.local/lib/python3.10/site-packages/starlette/middleware/base.py", line 141, in coro
    await self.app(scope, receive_or_disconnect, send_no_error)
  File "/home/saketh/.local/lib/python3.10/site-packages/starlette/middleware/cors.py", line 85, in __call__
    await self.app(scope, receive, send)
  File "/home/saketh/.local/lib/python3.10/site-packages/starlette/middleware/exceptions.py", line 62, in __call__
    await wrap_app_handling_exceptions(self.app, conn)(scope, receive, send)
  File "/home/saketh/.local/lib/python3.10/site-packages/starlette/_exception_handler.py", line 53, in wrapped_app
    raise exc
  File "/home/saketh/.local/lib/python3.10/site-packages/starlette/_exception_handler.py", line 42, in wrapped_app
    await app(scope, receive, sender)
  File "/home/saketh/.local/lib/python3.10/site-packages/starlette/routing.py", line 714, in __call__
    await self.middleware_stack(scope, receive, send)
  File "/home/saketh/.local/lib/python3.10/site-packages/starlette/routing.py", line 734, in app
    await route.handle(scope, receive, send)
  File "/home/saketh/.local/lib/python3.10/site-packages/starlette/routing.py", line 288, in handle
    await self.app(scope, receive, send)
  File "/home/saketh/.local/lib/python3.10/site-packages/starlette/routing.py", line 76, in app
    await wrap_app_handling_exceptions(app, request)(scope, receive, send)
  File "/home/saketh/.local/lib/python3.10/site-packages/starlette/_exception_handler.py", line 53, in wrapped_app
    raise exc
  File "/home/saketh/.local/lib/python3.10/site-packages/starlette/_exception_handler.py", line 42, in wrapped_app
    await app(scope, receive, sender)
  File "/home/saketh/.local/lib/python3.10/site-packages/starlette/routing.py", line 73, in app
    response = await f(request)
  File "/home/saketh/.local/lib/python3.10/site-packages/fastapi/routing.py", line 301, in app
    raw_response = await run_endpoint_function(
  File "/home/saketh/.local/lib/python3.10/site-packages/fastapi/routing.py", line 212, in run_endpoint_function
    return await dependant.call(**values)
  File "/home/saketh/Projects/dsa/src/main.py", line 152, in health
    "database": "connected" if db_pool and not db_pool._closed else "disconnected",
AttributeError: 'DatabasePool' object has no attribute '_closed'. Did you mean: 'close'?
WARNING:  WatchFiles detected changes in 'src/main.py'. Reloading...
INFO:     Shutting down
INFO:     Waiting for application shutdown.
INFO:src.main:Shutting down DSA Platform...
INFO:src.workers.job_worker:Stopping job worker...
INFO:src.main:Shutdown complete
INFO:     Application shutdown complete.
INFO:     Finished server process [20541]
/home/saketh/.local/lib/python3.10/site-packages/pydantic/_internal/_config.py:373: UserWarning: Valid config keys have changed in V2:
* 'allow_population_by_field_name' has been renamed to 'validate_by_name'
  warnings.warn(message, UserWarning)
/home/saketh/.local/lib/python3.10/site-packages/pydantic/_internal/_config.py:373: UserWarning: Valid config keys have changed in V2:
* 'schema_extra' has been renamed to 'json_schema_extra'
  warnings.warn(message, UserWarning)
INFO:src.api.error_handlers:Error handlers registered successfully
INFO:     Started server process [20747]
INFO:     Waiting for application startup.
INFO:src.main:Starting DSA Platform...
INFO:src.main:Database pool initialized
INFO:src.workers.job_worker:Registered executor for job type: import
INFO:src.workers.job_worker:Registered executor for job type: sampling
INFO:src.workers.job_worker:Registered executor for job type: exploration
INFO:src.workers.job_worker:Registered executor for job type: sql_transform
INFO:src.main:Job worker started
INFO:src.workers.job_worker:Starting job worker...
INFO:     Application startup complete.
[1;34mUpgrade to ydata-sdk[0m
Improve your data and profiling with ydata-sdk, featuring data quality scoring, redundancy detection, outlier identification, text validation, and synthetic data generation.
Register at https://ydata.ai/register
INFO:     127.0.0.1:54348 - "GET /health HTTP/1.1" 200 OK
INFO:     127.0.0.1:48502 - "POST /api/v1/login HTTP/1.1" 404 Not Found
INFO:     127.0.0.1:34580 - "POST /api/v1/users/login HTTP/1.1" 422 Unprocessable Entity
INFO:     127.0.0.1:40048 - "POST /api/v1/users/login HTTP/1.1" 200 OK
INFO:     127.0.0.1:52642 - "GET /api/v1/datasets HTTP/1.1" 307 Temporary Redirect
INFO:     127.0.0.1:57684 - "GET /api/v1/datasets/ HTTP/1.1" 200 OK
INFO:     127.0.0.1:59378 - "GET /api/v1/datasets/87 HTTP/1.1" 400 Bad Request
